<mujoco model="scene">
  <compiler autolimits="true" angle="radian"/>
  <option timestep="0.01" gravity="0 0 -9.8100000000000005" integrator="RK4"/>
  <visual>
    <headlight active="0"/>
  </visual>
  <default>
    <default class="/"/>
    <default class="mbs0/"/>
    <default class="mbs1/"/>
    <default class="mbs2/"/>
    <default class="mbs3/"/>
    <default class="mbs4/"/>
    <default class="mbs5/"/>
    <default class="mbs6/"/>
  </default>
  <asset>
    <material name="heightmap_0_material" class="/" texrepeat="1 1" emission="0" specular="0.5" shininess="0.5" reflectance="0" rgba="0.39215686274509803 0.39215686274509803 0.39215686274509803 1"/>
    <material name="mbs1/geom_mbs1_geom0_material" class="mbs1/" texrepeat="1 1" emission="0" specular="0.5" shininess="0.5" reflectance="0" rgba="1 0.19607843137254902 0.19607843137254902 1"/>
    <material name="mbs2/geom_mbs2_geom0_material" class="mbs2/" texrepeat="1 1" emission="0" specular="0.5" shininess="0.5" reflectance="0" rgba="1 0.19607843137254902 0.19607843137254902 1"/>
    <material name="mbs2/geom_mbs2_geom1_material" class="mbs2/" texrepeat="1 1" emission="0" specular="0.5" shininess="0.5" reflectance="0" rgba="1 1 1 1"/>
    <material name="mbs2/geom_mbs2_geom2_material" class="mbs2/" texrepeat="1 1" emission="0" specular="0.5" shininess="0.5" reflectance="0" rgba="1 1 1 1"/>
    <material name="mbs2/geom_mbs2_geom3_material" class="mbs2/" texrepeat="1 1" emission="0" specular="0.5" shininess="0.5" reflectance="0" rgba="1 1 1 1"/>
    <material name="mbs2/geom_mbs2_geom4_material" class="mbs2/" texrepeat="1 1" emission="0" specular="0.5" shininess="0.5" reflectance="0" rgba="1 1 1 1"/>
    <material name="mbs2/geom_mbs2_link0_geom0_material" class="mbs2/" texrepeat="1 1" emission="0" specular="0.5" shininess="0.5" reflectance="0" rgba="1 1 1 1"/>
    <material name="mbs2/geom_mbs2_link0_geom1_material" class="mbs2/" texrepeat="1 1" emission="0" specular="0.5" shininess="0.5" reflectance="0" rgba="1 1 1 1"/>
    <material name="mbs2/geom_mbs2_link0_geom2_material" class="mbs2/" texrepeat="1 1" emission="0" specular="0.5" shininess="0.5" reflectance="0" rgba="1 1 1 1"/>
    <material name="mbs2/geom_mbs2_link0_link1_geom0_material" class="mbs2/" texrepeat="1 1" emission="0" specular="0.5" shininess="0.5" reflectance="0" rgba="1 1 1 1"/>
    <material name="mbs2/geom_mbs2_link0_link1_geom1_material" class="mbs2/" texrepeat="1 1" emission="0" specular="0.5" shininess="0.5" reflectance="0" rgba="1 1 1 1"/>
    <material name="mbs2/geom_mbs2_link0_link1_geom2_material" class="mbs2/" texrepeat="1 1" emission="0" specular="0.5" shininess="0.5" reflectance="0" rgba="1 1 1 1"/>
    <material name="mbs2/geom_mbs2_link0_link1_link1_geom0_material" class="mbs2/" texrepeat="1 1" emission="0" specular="0.5" shininess="0.5" reflectance="0" rgba="1 1 1 1"/>
    <material name="mbs2/geom_mbs2_link0_link1_link1_geom1_material" class="mbs2/" texrepeat="1 1" emission="0" specular="0.5" shininess="0.5" reflectance="0" rgba="1 1 1 1"/>
    <material name="mbs2/geom_mbs2_link0_link1_link1_geom2_material" class="mbs2/" texrepeat="1 1" emission="0" specular="0.5" shininess="0.5" reflectance="0" rgba="1 1 1 1"/>
    <material name="mbs2/geom_mbs2_link0_link1_link1_link1_geom0_material" class="mbs2/" texrepeat="1 1" emission="0" specular="0.5" shininess="0.5" reflectance="0" rgba="1 1 1 1"/>
    <material name="mbs2/geom_mbs2_link0_link1_link1_link1_geom1_material" class="mbs2/" texrepeat="1 1" emission="0" specular="0.5" shininess="0.5" reflectance="0" rgba="1 1 1 1"/>
    <material name="mbs2/geom_mbs2_link0_link1_link1_link1_geom2_material" class="mbs2/" texrepeat="1 1" emission="0" specular="0.5" shininess="0.5" reflectance="0" rgba="1 1 1 1"/>
    <material name="mbs2/geom_mbs2_link0_link1_link1_link1_link1_geom0_material" class="mbs2/" texrepeat="1 1" emission="0" specular="0.5" shininess="0.5" reflectance="0" rgba="1 1 1 1"/>
    <material name="mbs2/geom_mbs2_link0_link1_link1_link1_link1_geom1_material" class="mbs2/" texrepeat="1 1" emission="0" specular="0.5" shininess="0.5" reflectance="0" rgba="1 1 1 1"/>
    <material name="mbs2/geom_mbs2_link1_geom0_material" class="mbs2/" texrepeat="1 1" emission="0" specular="0.5" shininess="0.5" reflectance="0" rgba="1 1 1 1"/>
    <material name="mbs2/geom_mbs2_link1_geom1_material" class="mbs2/" texrepeat="1 1" emission="0" specular="0.5" shininess="0.5" reflectance="0" rgba="1 1 1 1"/>
    <material name="mbs2/geom_mbs2_link1_geom2_material" class="mbs2/" texrepeat="1 1" emission="0" specular="0.5" shininess="0.5" reflectance="0" rgba="1 1 1 1"/>
    <material name="mbs2/geom_mbs2_link1_link1_geom0_material" class="mbs2/" texrepeat="1 1" emission="0" specular="0.5" shininess="0.5" reflectance="0" rgba="1 1 1 1"/>
    <material name="mbs2/geom_mbs2_link1_link1_geom1_material" class="mbs2/" texrepeat="1 1" emission="0" specular="0.5" shininess="0.5" reflectance="0" rgba="1 1 1 1"/>
    <material name="mbs2/geom_mbs2_link1_link1_geom2_material" class="mbs2/" texrepeat="1 1" emission="0" specular="0.5" shininess="0.5" reflectance="0" rgba="1 1 1 1"/>
    <material name="mbs2/geom_mbs2_link1_link1_link1_geom0_material" class="mbs2/" texrepeat="1 1" emission="0" specular="0.5" shininess="0.5" reflectance="0" rgba="1 1 1 1"/>
    <material name="mbs2/geom_mbs2_link1_link1_link1_geom1_material" class="mbs2/" texrepeat="1 1" emission="0" specular="0.5" shininess="0.5" reflectance="0" rgba="1 1 1 1"/>
    <material name="mbs2/geom_mbs2_link1_link1_link1_geom2_material" class="mbs2/" texrepeat="1 1" emission="0" specular="0.5" shininess="0.5" reflectance="0" rgba="1 1 1 1"/>
    <material name="mbs2/geom_mbs2_link1_link1_link1_link1_geom0_material" class="mbs2/" texrepeat="1 1" emission="0" specular="0.5" shininess="0.5" reflectance="0" rgba="1 1 1 1"/>
    <material name="mbs2/geom_mbs2_link1_link1_link1_link1_geom1_material" class="mbs2/" texrepeat="1 1" emission="0" specular="0.5" shininess="0.5" reflectance="0" rgba="1 1 1 1"/>
    <material name="mbs2/geom_mbs2_link1_link1_link1_link1_geom2_material" class="mbs2/" texrepeat="1 1" emission="0" specular="0.5" shininess="0.5" reflectance="0" rgba="1 1 1 1"/>
    <material name="mbs2/geom_mbs2_link1_link1_link1_link1_link1_geom0_material" class="mbs2/" texrepeat="1 1" emission="0" specular="0.5" shininess="0.5" reflectance="0" rgba="1 1 1 1"/>
    <material name="mbs2/geom_mbs2_link1_link1_link1_link1_link1_geom1_material" class="mbs2/" texrepeat="1 1" emission="0" specular="0.5" shininess="0.5" reflectance="0" rgba="1 1 1 1"/>
    <material name="mbs2/geom_mbs2_link2_geom0_material" class="mbs2/" texrepeat="1 1" emission="0" specular="0.5" shininess="0.5" reflectance="0" rgba="1 1 1 1"/>
    <material name="mbs2/geom_mbs2_link2_geom1_material" class="mbs2/" texrepeat="1 1" emission="0" specular="0.5" shininess="0.5" reflectance="0" rgba="1 1 1 1"/>
    <material name="mbs2/geom_mbs2_link2_geom2_material" class="mbs2/" texrepeat="1 1" emission="0" specular="0.5" shininess="0.5" reflectance="0" rgba="1 1 1 1"/>
    <material name="mbs2/geom_mbs2_link2_link1_geom0_material" class="mbs2/" texrepeat="1 1" emission="0" specular="0.5" shininess="0.5" reflectance="0" rgba="1 1 1 1"/>
    <material name="mbs2/geom_mbs2_link2_link1_geom1_material" class="mbs2/" texrepeat="1 1" emission="0" specular="0.5" shininess="0.5" reflectance="0" rgba="1 1 1 1"/>
    <material name="mbs2/geom_mbs2_link2_link1_geom2_material" class="mbs2/" texrepeat="1 1" emission="0" specular="0.5" shininess="0.5" reflectance="0" rgba="1 1 1 1"/>
    <material name="mbs2/geom_mbs2_link2_link1_link1_geom0_material" class="mbs2/" texrepeat="1 1" emission="0" specular="0.5" shininess="0.5" reflectance="0" rgba="1 1 1 1"/>
    <material name="mbs2/geom_mbs2_link2_link1_link1_geom1_material" class="mbs2/" texrepeat="1 1" emission="0" specular="0.5" shininess="0.5" reflectance="0" rgba="1 1 1 1"/>
    <material name="mbs2/geom_mbs2_link2_link1_link1_geom2_material" class="mbs2/" texrepeat="1 1" emission="0" specular="0.5" shininess="0.5" reflectance="0" rgba="1 1 1 1"/>
    <material name="mbs2/geom_mbs2_link2_link1_link1_link1_geom0_material" class="mbs2/" texrepeat="1 1" emission="0" specular="0.5" shininess="0.5" reflectance="0" rgba="1 1 1 1"/>
    <material name="mbs2/geom_mbs2_link2_link1_link1_link1_geom1_material" class="mbs2/" texrepeat="1 1" emission="0" specular="0.5" shininess="0.5" reflectance="0" rgba="1 1 1 1"/>
    <material name="mbs2/geom_mbs2_link3_geom0_material" class="mbs2/" texrepeat="1 1" emission="0" specular="0.5" shininess="0.5" reflectance="0" rgba="1 1 1 1"/>
    <material name="mbs2/geom_mbs2_link3_geom1_material" class="mbs2/" texrepeat="1 1" emission="0" specular="0.5" shininess="0.5" reflectance="0" rgba="1 1 1 1"/>
    <material name="mbs2/geom_mbs2_link3_geom2_material" class="mbs2/" texrepeat="1 1" emission="0" specular="0.5" shininess="0.5" reflectance="0" rgba="1 1 1 1"/>
    <material name="mbs2/geom_mbs2_link3_link1_geom0_material" class="mbs2/" texrepeat="1 1" emission="0" specular="0.5" shininess="0.5" reflectance="0" rgba="1 1 1 1"/>
    <material name="mbs2/geom_mbs2_link3_link1_geom1_material" class="mbs2/" texrepeat="1 1" emission="0" specular="0.5" shininess="0.5" reflectance="0" rgba="1 1 1 1"/>
    <material name="mbs2/geom_mbs2_link3_link1_geom2_material" class="mbs2/" texrepeat="1 1" emission="0" specular="0.5" shininess="0.5" reflectance="0" rgba="1 1 1 1"/>
    <material name="mbs2/geom_mbs2_link3_link1_link1_geom0_material" class="mbs2/" texrepeat="1 1" emission="0" specular="0.5" shininess="0.5" reflectance="0" rgba="1 1 1 1"/>
    <material name="mbs2/geom_mbs2_link3_link1_link1_geom1_material" class="mbs2/" texrepeat="1 1" emission="0" specular="0.5" shininess="0.5" reflectance="0" rgba="1 1 1 1"/>
    <material name="mbs2/geom_mbs2_link3_link1_link1_geom2_material" class="mbs2/" texrepeat="1 1" emission="0" specular="0.5" shininess="0.5" reflectance="0" rgba="1 1 1 1"/>
    <material name="mbs2/geom_mbs2_link3_link1_link1_link1_geom0_material" class="mbs2/" texrepeat="1 1" emission="0" specular="0.5" shininess="0.5" reflectance="0" rgba="1 1 1 1"/>
    <material name="mbs2/geom_mbs2_link3_link1_link1_link1_geom1_material" class="mbs2/" texrepeat="1 1" emission="0" specular="0.5" shininess="0.5" reflectance="0" rgba="1 1 1 1"/>
    <material name="mbs2/geom_mbs2_link3_link1_link1_link1_geom2_material" class="mbs2/" texrepeat="1 1" emission="0" specular="0.5" shininess="0.5" reflectance="0" rgba="1 1 1 1"/>
    <material name="mbs2/geom_mbs2_link3_link1_link1_link1_link1_geom0_material" class="mbs2/" texrepeat="1 1" emission="0" specular="0.5" shininess="0.5" reflectance="0" rgba="1 1 1 1"/>
    <material name="mbs2/geom_mbs2_link3_link1_link1_link1_link1_geom1_material" class="mbs2/" texrepeat="1 1" emission="0" specular="0.5" shininess="0.5" reflectance="0" rgba="1 1 1 1"/>
    <material name="mbs3/geom_mbs3_geom0_material" class="mbs3/" texrepeat="1 1" emission="0" specular="0.5" shininess="0.5" reflectance="0" rgba="1 0.19607843137254902 0.19607843137254902 1"/>
    <material name="mbs3/geom_mbs3_geom1_material" class="mbs3/" texrepeat="1 1" emission="0" specular="0.5" shininess="0.5" reflectance="0" rgba="1 1 1 1"/>
    <material name="mbs3/geom_mbs3_geom2_material" class="mbs3/" texrepeat="1 1" emission="0" specular="0.5" shininess="0.5" reflectance="0" rgba="1 1 1 1"/>
    <material name="mbs3/geom_mbs3_geom3_material" class="mbs3/" texrepeat="1 1" emission="0" specular="0.5" shininess="0.5" reflectance="0" rgba="1 1 1 1"/>
    <material name="mbs3/geom_mbs3_geom4_material" class="mbs3/" texrepeat="1 1" emission="0" specular="0.5" shininess="0.5" reflectance="0" rgba="1 1 1 1"/>
    <material name="mbs3/geom_mbs3_link0_geom0_material" class="mbs3/" texrepeat="1 1" emission="0" specular="0.5" shininess="0.5" reflectance="0" rgba="1 1 1 1"/>
    <material name="mbs3/geom_mbs3_link0_geom1_material" class="mbs3/" texrepeat="1 1" emission="0" specular="0.5" shininess="0.5" reflectance="0" rgba="1 1 1 1"/>
    <material name="mbs3/geom_mbs3_link0_geom2_material" class="mbs3/" texrepeat="1 1" emission="0" specular="0.5" shininess="0.5" reflectance="0" rgba="1 1 1 1"/>
    <material name="mbs3/geom_mbs3_link0_link1_geom0_material" class="mbs3/" texrepeat="1 1" emission="0" specular="0.5" shininess="0.5" reflectance="0" rgba="1 1 1 1"/>
    <material name="mbs3/geom_mbs3_link0_link1_geom1_material" class="mbs3/" texrepeat="1 1" emission="0" specular="0.5" shininess="0.5" reflectance="0" rgba="1 1 1 1"/>
    <material name="mbs3/geom_mbs3_link0_link1_geom2_material" class="mbs3/" texrepeat="1 1" emission="0" specular="0.5" shininess="0.5" reflectance="0" rgba="1 1 1 1"/>
    <material name="mbs3/geom_mbs3_link0_link1_link1_geom0_material" class="mbs3/" texrepeat="1 1" emission="0" specular="0.5" shininess="0.5" reflectance="0" rgba="1 1 1 1"/>
    <material name="mbs3/geom_mbs3_link0_link1_link1_geom1_material" class="mbs3/" texrepeat="1 1" emission="0" specular="0.5" shininess="0.5" reflectance="0" rgba="1 1 1 1"/>
    <material name="mbs3/geom_mbs3_link0_link1_link1_geom2_material" class="mbs3/" texrepeat="1 1" emission="0" specular="0.5" shininess="0.5" reflectance="0" rgba="1 1 1 1"/>
    <material name="mbs3/geom_mbs3_link0_link1_link1_link1_geom0_material" class="mbs3/" texrepeat="1 1" emission="0" specular="0.5" shininess="0.5" reflectance="0" rgba="1 1 1 1"/>
    <material name="mbs3/geom_mbs3_link0_link1_link1_link1_geom1_material" class="mbs3/" texrepeat="1 1" emission="0" specular="0.5" shininess="0.5" reflectance="0" rgba="1 1 1 1"/>
    <material name="mbs3/geom_mbs3_link0_link1_link1_link1_geom2_material" class="mbs3/" texrepeat="1 1" emission="0" specular="0.5" shininess="0.5" reflectance="0" rgba="1 1 1 1"/>
    <material name="mbs3/geom_mbs3_link0_link1_link1_link1_link1_geom0_material" class="mbs3/" texrepeat="1 1" emission="0" specular="0.5" shininess="0.5" reflectance="0" rgba="1 1 1 1"/>
    <material name="mbs3/geom_mbs3_link0_link1_link1_link1_link1_geom1_material" class="mbs3/" texrepeat="1 1" emission="0" specular="0.5" shininess="0.5" reflectance="0" rgba="1 1 1 1"/>
    <material name="mbs3/geom_mbs3_link1_geom0_material" class="mbs3/" texrepeat="1 1" emission="0" specular="0.5" shininess="0.5" reflectance="0" rgba="1 1 1 1"/>
    <material name="mbs3/geom_mbs3_link1_geom1_material" class="mbs3/" texrepeat="1 1" emission="0" specular="0.5" shininess="0.5" reflectance="0" rgba="1 1 1 1"/>
    <material name="mbs3/geom_mbs3_link1_geom2_material" class="mbs3/" texrepeat="1 1" emission="0" specular="0.5" shininess="0.5" reflectance="0" rgba="1 1 1 1"/>
    <material name="mbs3/geom_mbs3_link1_link1_geom0_material" class="mbs3/" texrepeat="1 1" emission="0" specular="0.5" shininess="0.5" reflectance="0" rgba="1 1 1 1"/>
    <material name="mbs3/geom_mbs3_link1_link1_geom1_material" class="mbs3/" texrepeat="1 1" emission="0" specular="0.5" shininess="0.5" reflectance="0" rgba="1 1 1 1"/>
    <material name="mbs3/geom_mbs3_link1_link1_geom2_material" class="mbs3/" texrepeat="1 1" emission="0" specular="0.5" shininess="0.5" reflectance="0" rgba="1 1 1 1"/>
    <material name="mbs3/geom_mbs3_link1_link1_link1_geom0_material" class="mbs3/" texrepeat="1 1" emission="0" specular="0.5" shininess="0.5" reflectance="0" rgba="1 1 1 1"/>
    <material name="mbs3/geom_mbs3_link1_link1_link1_geom1_material" class="mbs3/" texrepeat="1 1" emission="0" specular="0.5" shininess="0.5" reflectance="0" rgba="1 1 1 1"/>
    <material name="mbs3/geom_mbs3_link1_link1_link1_geom2_material" class="mbs3/" texrepeat="1 1" emission="0" specular="0.5" shininess="0.5" reflectance="0" rgba="1 1 1 1"/>
    <material name="mbs3/geom_mbs3_link1_link1_link1_link1_geom0_material" class="mbs3/" texrepeat="1 1" emission="0" specular="0.5" shininess="0.5" reflectance="0" rgba="1 1 1 1"/>
    <material name="mbs3/geom_mbs3_link1_link1_link1_link1_geom1_material" class="mbs3/" texrepeat="1 1" emission="0" specular="0.5" shininess="0.5" reflectance="0" rgba="1 1 1 1"/>
    <material name="mbs3/geom_mbs3_link1_link1_link1_link1_geom2_material" class="mbs3/" texrepeat="1 1" emission="0" specular="0.5" shininess="0.5" reflectance="0" rgba="1 1 1 1"/>
    <material name="mbs3/geom_mbs3_link1_link1_link1_link1_link1_geom0_material" class="mbs3/" texrepeat="1 1" emission="0" specular="0.5" shininess="0.5" reflectance="0" rgba="1 1 1 1"/>
    <material name="mbs3/geom_mbs3_link1_link1_link1_link1_link1_geom1_material" class="mbs3/" texrepeat="1 1" emission="0" specular="0.5" shininess="0.5" reflectance="0" rgba="1 1 1 1"/>
    <material name="mbs3/geom_mbs3_link2_geom0_material" class="mbs3/" texrepeat="1 1" emission="0" specular="0.5" shininess="0.5" reflectance="0" rgba="1 1 1 1"/>
    <material name="mbs3/geom_mbs3_link2_geom1_material" class="mbs3/" texrepeat="1 1" emission="0" specular="0.5" shininess="0.5" reflectance="0" rgba="1 1 1 1"/>
    <material name="mbs3/geom_mbs3_link2_geom2_material" class="mbs3/" texrepeat="1 1" emission="0" specular="0.5" shininess="0.5" reflectance="0" rgba="1 1 1 1"/>
    <material name="mbs3/geom_mbs3_link2_link1_geom0_material" class="mbs3/" texrepeat="1 1" emission="0" specular="0.5" shininess="0.5" reflectance="0" rgba="1 1 1 1"/>
    <material name="mbs3/geom_mbs3_link2_link1_geom1_material" class="mbs3/" texrepeat="1 1" emission="0" specular="0.5" shininess="0.5" reflectance="0" rgba="1 1 1 1"/>
    <material name="mbs3/geom_mbs3_link2_link1_geom2_material" class="mbs3/" texrepeat="1 1" emission="0" specular="0.5" shininess="0.5" reflectance="0" rgba="1 1 1 1"/>
    <material name="mbs3/geom_mbs3_link2_link1_link1_geom0_material" class="mbs3/" texrepeat="1 1" emission="0" specular="0.5" shininess="0.5" reflectance="0" rgba="1 1 1 1"/>
    <material name="mbs3/geom_mbs3_link2_link1_link1_geom1_material" class="mbs3/" texrepeat="1 1" emission="0" specular="0.5" shininess="0.5" reflectance="0" rgba="1 1 1 1"/>
    <material name="mbs3/geom_mbs3_link2_link1_link1_geom2_material" class="mbs3/" texrepeat="1 1" emission="0" specular="0.5" shininess="0.5" reflectance="0" rgba="1 1 1 1"/>
    <material name="mbs3/geom_mbs3_link2_link1_link1_link1_geom0_material" class="mbs3/" texrepeat="1 1" emission="0" specular="0.5" shininess="0.5" reflectance="0" rgba="1 1 1 1"/>
    <material name="mbs3/geom_mbs3_link2_link1_link1_link1_geom1_material" class="mbs3/" texrepeat="1 1" emission="0" specular="0.5" shininess="0.5" reflectance="0" rgba="1 1 1 1"/>
    <material name="mbs3/geom_mbs3_link3_geom0_material" class="mbs3/" texrepeat="1 1" emission="0" specular="0.5" shininess="0.5" reflectance="0" rgba="1 1 1 1"/>
    <material name="mbs3/geom_mbs3_link3_geom1_material" class="mbs3/" texrepeat="1 1" emission="0" specular="0.5" shininess="0.5" reflectance="0" rgba="1 1 1 1"/>
    <material name="mbs3/geom_mbs3_link3_geom2_material" class="mbs3/" texrepeat="1 1" emission="0" specular="0.5" shininess="0.5" reflectance="0" rgba="1 1 1 1"/>
    <material name="mbs3/geom_mbs3_link3_link1_geom0_material" class="mbs3/" texrepeat="1 1" emission="0" specular="0.5" shininess="0.5" reflectance="0" rgba="1 1 1 1"/>
    <material name="mbs3/geom_mbs3_link3_link1_geom1_material" class="mbs3/" texrepeat="1 1" emission="0" specular="0.5" shininess="0.5" reflectance="0" rgba="1 1 1 1"/>
    <material name="mbs3/geom_mbs3_link3_link1_geom2_material" class="mbs3/" texrepeat="1 1" emission="0" specular="0.5" shininess="0.5" reflectance="0" rgba="1 1 1 1"/>
    <material name="mbs3/geom_mbs3_link3_link1_link1_geom0_material" class="mbs3/" texrepeat="1 1" emission="0" specular="0.5" shininess="0.5" reflectance="0" rgba="1 1 1 1"/>
    <material name="mbs3/geom_mbs3_link3_link1_link1_geom1_material" class="mbs3/" texrepeat="1 1" emission="0" specular="0.5" shininess="0.5" reflectance="0" rgba="1 1 1 1"/>
    <material name="mbs3/geom_mbs3_link3_link1_link1_geom2_material" class="mbs3/" texrepeat="1 1" emission="0" specular="0.5" shininess="0.5" reflectance="0" rgba="1 1 1 1"/>
    <material name="mbs3/geom_mbs3_link3_link1_link1_link1_geom0_material" class="mbs3/" texrepeat="1 1" emission="0" specular="0.5" shininess="0.5" reflectance="0" rgba="1 1 1 1"/>
    <material name="mbs3/geom_mbs3_link3_link1_link1_link1_geom1_material" class="mbs3/" texrepeat="1 1" emission="0" specular="0.5" shininess="0.5" reflectance="0" rgba="1 1 1 1"/>
    <material name="mbs3/geom_mbs3_link3_link1_link1_link1_geom2_material" class="mbs3/" texrepeat="1 1" emission="0" specular="0.5" shininess="0.5" reflectance="0" rgba="1 1 1 1"/>
    <material name="mbs3/geom_mbs3_link3_link1_link1_link1_link1_geom0_material" class="mbs3/" texrepeat="1 1" emission="0" specular="0.5" shininess="0.5" reflectance="0" rgba="1 1 1 1"/>
    <material name="mbs3/geom_mbs3_link3_link1_link1_link1_link1_geom1_material" class="mbs3/" texrepeat="1 1" emission="0" specular="0.5" shininess="0.5" reflectance="0" rgba="1 1 1 1"/>
    <material name="mbs4/geom_mbs4_geom0_material" class="mbs4/" texrepeat="1 1" emission="0" specular="0.5" shininess="0.5" reflectance="0" rgba="1 0.19607843137254902 0.19607843137254902 1"/>
    <material name="mbs4/geom_mbs4_geom1_material" class="mbs4/" texrepeat="1 1" emission="0" specular="0.5" shininess="0.5" reflectance="0" rgba="1 1 1 1"/>
    <material name="mbs4/geom_mbs4_geom2_material" class="mbs4/" texrepeat="1 1" emission="0" specular="0.5" shininess="0.5" reflectance="0" rgba="1 1 1 1"/>
    <material name="mbs4/geom_mbs4_geom3_material" class="mbs4/" texrepeat="1 1" emission="0" specular="0.5" shininess="0.5" reflectance="0" rgba="1 1 1 1"/>
    <material name="mbs4/geom_mbs4_geom4_material" class="mbs4/" texrepeat="1 1" emission="0" specular="0.5" shininess="0.5" reflectance="0" rgba="1 1 1 1"/>
    <material name="mbs4/geom_mbs4_link0_geom0_material" class="mbs4/" texrepeat="1 1" emission="0" specular="0.5" shininess="0.5" reflectance="0" rgba="1 1 1 1"/>
    <material name="mbs4/geom_mbs4_link0_geom1_material" class="mbs4/" texrepeat="1 1" emission="0" specular="0.5" shininess="0.5" reflectance="0" rgba="1 1 1 1"/>
    <material name="mbs4/geom_mbs4_link0_geom2_material" class="mbs4/" texrepeat="1 1" emission="0" specular="0.5" shininess="0.5" reflectance="0" rgba="1 1 1 1"/>
    <material name="mbs4/geom_mbs4_link0_link1_geom0_material" class="mbs4/" texrepeat="1 1" emission="0" specular="0.5" shininess="0.5" reflectance="0" rgba="1 1 1 1"/>
    <material name="mbs4/geom_mbs4_link0_link1_geom1_material" class="mbs4/" texrepeat="1 1" emission="0" specular="0.5" shininess="0.5" reflectance="0" rgba="1 1 1 1"/>
    <material name="mbs4/geom_mbs4_link0_link1_geom2_material" class="mbs4/" texrepeat="1 1" emission="0" specular="0.5" shininess="0.5" reflectance="0" rgba="1 1 1 1"/>
    <material name="mbs4/geom_mbs4_link0_link1_link1_geom0_material" class="mbs4/" texrepeat="1 1" emission="0" specular="0.5" shininess="0.5" reflectance="0" rgba="1 1 1 1"/>
    <material name="mbs4/geom_mbs4_link0_link1_link1_geom1_material" class="mbs4/" texrepeat="1 1" emission="0" specular="0.5" shininess="0.5" reflectance="0" rgba="1 1 1 1"/>
    <material name="mbs4/geom_mbs4_link0_link1_link1_geom2_material" class="mbs4/" texrepeat="1 1" emission="0" specular="0.5" shininess="0.5" reflectance="0" rgba="1 1 1 1"/>
    <material name="mbs4/geom_mbs4_link0_link1_link1_link1_geom0_material" class="mbs4/" texrepeat="1 1" emission="0" specular="0.5" shininess="0.5" reflectance="0" rgba="1 1 1 1"/>
    <material name="mbs4/geom_mbs4_link0_link1_link1_link1_geom1_material" class="mbs4/" texrepeat="1 1" emission="0" specular="0.5" shininess="0.5" reflectance="0" rgba="1 1 1 1"/>
    <material name="mbs4/geom_mbs4_link0_link1_link1_link1_geom2_material" class="mbs4/" texrepeat="1 1" emission="0" specular="0.5" shininess="0.5" reflectance="0" rgba="1 1 1 1"/>
    <material name="mbs4/geom_mbs4_link0_link1_link1_link1_link1_geom0_material" class="mbs4/" texrepeat="1 1" emission="0" specular="0.5" shininess="0.5" reflectance="0" rgba="1 1 1 1"/>
    <material name="mbs4/geom_mbs4_link0_link1_link1_link1_link1_geom1_material" class="mbs4/" texrepeat="1 1" emission="0" specular="0.5" shininess="0.5" reflectance="0" rgba="1 1 1 1"/>
    <material name="mbs4/geom_mbs4_link1_geom0_material" class="mbs4/" texrepeat="1 1" emission="0" specular="0.5" shininess="0.5" reflectance="0" rgba="1 1 1 1"/>
    <material name="mbs4/geom_mbs4_link1_geom1_material" class="mbs4/" texrepeat="1 1" emission="0" specular="0.5" shininess="0.5" reflectance="0" rgba="1 1 1 1"/>
    <material name="mbs4/geom_mbs4_link1_geom2_material" class="mbs4/" texrepeat="1 1" emission="0" specular="0.5" shininess="0.5" reflectance="0" rgba="1 1 1 1"/>
    <material name="mbs4/geom_mbs4_link1_link1_geom0_material" class="mbs4/" texrepeat="1 1" emission="0" specular="0.5" shininess="0.5" reflectance="0" rgba="1 1 1 1"/>
    <material name="mbs4/geom_mbs4_link1_link1_geom1_material" class="mbs4/" texrepeat="1 1" emission="0" specular="0.5" shininess="0.5" reflectance="0" rgba="1 1 1 1"/>
    <material name="mbs4/geom_mbs4_link1_link1_geom2_material" class="mbs4/" texrepeat="1 1" emission="0" specular="0.5" shininess="0.5" reflectance="0" rgba="1 1 1 1"/>
    <material name="mbs4/geom_mbs4_link1_link1_link1_geom0_material" class="mbs4/" texrepeat="1 1" emission="0" specular="0.5" shininess="0.5" reflectance="0" rgba="1 1 1 1"/>
    <material name="mbs4/geom_mbs4_link1_link1_link1_geom1_material" class="mbs4/" texrepeat="1 1" emission="0" specular="0.5" shininess="0.5" reflectance="0" rgba="1 1 1 1"/>
    <material name="mbs4/geom_mbs4_link1_link1_link1_geom2_material" class="mbs4/" texrepeat="1 1" emission="0" specular="0.5" shininess="0.5" reflectance="0" rgba="1 1 1 1"/>
    <material name="mbs4/geom_mbs4_link1_link1_link1_link1_geom0_material" class="mbs4/" texrepeat="1 1" emission="0" specular="0.5" shininess="0.5" reflectance="0" rgba="1 1 1 1"/>
    <material name="mbs4/geom_mbs4_link1_link1_link1_link1_geom1_material" class="mbs4/" texrepeat="1 1" emission="0" specular="0.5" shininess="0.5" reflectance="0" rgba="1 1 1 1"/>
    <material name="mbs4/geom_mbs4_link1_link1_link1_link1_geom2_material" class="mbs4/" texrepeat="1 1" emission="0" specular="0.5" shininess="0.5" reflectance="0" rgba="1 1 1 1"/>
    <material name="mbs4/geom_mbs4_link1_link1_link1_link1_link1_geom0_material" class="mbs4/" texrepeat="1 1" emission="0" specular="0.5" shininess="0.5" reflectance="0" rgba="1 1 1 1"/>
    <material name="mbs4/geom_mbs4_link1_link1_link1_link1_link1_geom1_material" class="mbs4/" texrepeat="1 1" emission="0" specular="0.5" shininess="0.5" reflectance="0" rgba="1 1 1 1"/>
    <material name="mbs4/geom_mbs4_link2_geom0_material" class="mbs4/" texrepeat="1 1" emission="0" specular="0.5" shininess="0.5" reflectance="0" rgba="1 1 1 1"/>
    <material name="mbs4/geom_mbs4_link2_geom1_material" class="mbs4/" texrepeat="1 1" emission="0" specular="0.5" shininess="0.5" reflectance="0" rgba="1 1 1 1"/>
    <material name="mbs4/geom_mbs4_link2_geom2_material" class="mbs4/" texrepeat="1 1" emission="0" specular="0.5" shininess="0.5" reflectance="0" rgba="1 1 1 1"/>
    <material name="mbs4/geom_mbs4_link2_link1_geom0_material" class="mbs4/" texrepeat="1 1" emission="0" specular="0.5" shininess="0.5" reflectance="0" rgba="1 1 1 1"/>
    <material name="mbs4/geom_mbs4_link2_link1_geom1_material" class="mbs4/" texrepeat="1 1" emission="0" specular="0.5" shininess="0.5" reflectance="0" rgba="1 1 1 1"/>
    <material name="mbs4/geom_mbs4_link2_link1_geom2_material" class="mbs4/" texrepeat="1 1" emission="0" specular="0.5" shininess="0.5" reflectance="0" rgba="1 1 1 1"/>
    <material name="mbs4/geom_mbs4_link2_link1_link1_geom0_material" class="mbs4/" texrepeat="1 1" emission="0" specular="0.5" shininess="0.5" reflectance="0" rgba="1 1 1 1"/>
    <material name="mbs4/geom_mbs4_link2_link1_link1_geom1_material" class="mbs4/" texrepeat="1 1" emission="0" specular="0.5" shininess="0.5" reflectance="0" rgba="1 1 1 1"/>
    <material name="mbs4/geom_mbs4_link2_link1_link1_geom2_material" class="mbs4/" texrepeat="1 1" emission="0" specular="0.5" shininess="0.5" reflectance="0" rgba="1 1 1 1"/>
    <material name="mbs4/geom_mbs4_link2_link1_link1_link1_geom0_material" class="mbs4/" texrepeat="1 1" emission="0" specular="0.5" shininess="0.5" reflectance="0" rgba="1 1 1 1"/>
    <material name="mbs4/geom_mbs4_link2_link1_link1_link1_geom1_material" class="mbs4/" texrepeat="1 1" emission="0" specular="0.5" shininess="0.5" reflectance="0" rgba="1 1 1 1"/>
    <material name="mbs4/geom_mbs4_link3_geom0_material" class="mbs4/" texrepeat="1 1" emission="0" specular="0.5" shininess="0.5" reflectance="0" rgba="1 1 1 1"/>
    <material name="mbs4/geom_mbs4_link3_geom1_material" class="mbs4/" texrepeat="1 1" emission="0" specular="0.5" shininess="0.5" reflectance="0" rgba="1 1 1 1"/>
    <material name="mbs4/geom_mbs4_link3_geom2_material" class="mbs4/" texrepeat="1 1" emission="0" specular="0.5" shininess="0.5" reflectance="0" rgba="1 1 1 1"/>
    <material name="mbs4/geom_mbs4_link3_link1_geom0_material" class="mbs4/" texrepeat="1 1" emission="0" specular="0.5" shininess="0.5" reflectance="0" rgba="1 1 1 1"/>
    <material name="mbs4/geom_mbs4_link3_link1_geom1_material" class="mbs4/" texrepeat="1 1" emission="0" specular="0.5" shininess="0.5" reflectance="0" rgba="1 1 1 1"/>
    <material name="mbs4/geom_mbs4_link3_link1_geom2_material" class="mbs4/" texrepeat="1 1" emission="0" specular="0.5" shininess="0.5" reflectance="0" rgba="1 1 1 1"/>
    <material name="mbs4/geom_mbs4_link3_link1_link1_geom0_material" class="mbs4/" texrepeat="1 1" emission="0" specular="0.5" shininess="0.5" reflectance="0" rgba="1 1 1 1"/>
    <material name="mbs4/geom_mbs4_link3_link1_link1_geom1_material" class="mbs4/" texrepeat="1 1" emission="0" specular="0.5" shininess="0.5" reflectance="0" rgba="1 1 1 1"/>
    <material name="mbs4/geom_mbs4_link3_link1_link1_geom2_material" class="mbs4/" texrepeat="1 1" emission="0" specular="0.5" shininess="0.5" reflectance="0" rgba="1 1 1 1"/>
    <material name="mbs4/geom_mbs4_link3_link1_link1_link1_geom0_material" class="mbs4/" texrepeat="1 1" emission="0" specular="0.5" shininess="0.5" reflectance="0" rgba="1 1 1 1"/>
    <material name="mbs4/geom_mbs4_link3_link1_link1_link1_geom1_material" class="mbs4/" texrepeat="1 1" emission="0" specular="0.5" shininess="0.5" reflectance="0" rgba="1 1 1 1"/>
    <material name="mbs4/geom_mbs4_link3_link1_link1_link1_geom2_material" class="mbs4/" texrepeat="1 1" emission="0" specular="0.5" shininess="0.5" reflectance="0" rgba="1 1 1 1"/>
    <material name="mbs4/geom_mbs4_link3_link1_link1_link1_link1_geom0_material" class="mbs4/" texrepeat="1 1" emission="0" specular="0.5" shininess="0.5" reflectance="0" rgba="1 1 1 1"/>
    <material name="mbs4/geom_mbs4_link3_link1_link1_link1_link1_geom1_material" class="mbs4/" texrepeat="1 1" emission="0" specular="0.5" shininess="0.5" reflectance="0" rgba="1 1 1 1"/>
    <material name="mbs5/geom_mbs5_geom0_material" class="mbs5/" texrepeat="1 1" emission="0" specular="0.5" shininess="0.5" reflectance="0" rgba="1 0.19607843137254902 0.19607843137254902 1"/>
    <material name="mbs6/geom_mbs6_geom0_material" class="mbs6/" texrepeat="1 1" emission="0" specular="0.5" shininess="0.5" reflectance="0" rgba="1 0.19607843137254902 0.19607843137254902 1"/>
    <material name="mbs6/geom_mbs6_geom1_material" class="mbs6/" texrepeat="1 1" emission="0" specular="0.5" shininess="0.5" reflectance="0" rgba="0.19607843137254902 0.19607843137254902 1 1"/>
    <material name="mbs6/geom_mbs6_geom2_material" class="mbs6/" texrepeat="1 1" emission="0" specular="0.5" shininess="0.5" reflectance="0" rgba="0.19607843137254902 0.19607843137254902 1 1"/>
    <material name="mbs6/geom_mbs6_geom3_material" class="mbs6/" texrepeat="1 1" emission="0" specular="0.5" shininess="0.5" reflectance="0" rgba="0.19607843137254902 0.19607843137254902 1 1"/>
    <material name="mbs6/geom_mbs6_geom4_material" class="mbs6/" texrepeat="1 1" emission="0" specular="0.5" shininess="0.5" reflectance="0" rgba="0.19607843137254902 0.19607843137254902 1 1"/>
    <material name="mbs6/geom_mbs6_geom5_material" class="mbs6/" texrepeat="1 1" emission="0" specular="0.5" shininess="0.5" reflectance="0" rgba="0.19607843137254902 0.19607843137254902 1 1"/>
    <material name="mbs6/geom_mbs6_geom6_material" class="mbs6/" texrepeat="1 1" emission="0" specular="0.5" shininess="0.5" reflectance="0" rgba="0.19607843137254902 0.19607843137254902 1 1"/>
    <material name="mbs6/geom_mbs6_geom7_material" class="mbs6/" texrepeat="1 1" emission="0" specular="0.5" shininess="0.5" reflectance="0" rgba="0.19607843137254902 0.19607843137254902 1 1"/>
    <material name="mbs6/geom_mbs6_geom8_material" class="mbs6/" texrepeat="1 1" emission="0" specular="0.5" shininess="0.5" reflectance="0" rgba="0.19607843137254902 0.19607843137254902 1 1"/>
    <material name="mbs6/geom_mbs6_geom9_material" class="mbs6/" texrepeat="1 1" emission="0" specular="0.5" shininess="0.5" reflectance="0" rgba="0.19607843137254902 0.19607843137254902 1 1"/>
    <material name="mbs6/geom_mbs6_geom10_material" class="mbs6/" texrepeat="1 1" emission="0" specular="0.5" shininess="0.5" reflectance="0" rgba="0.19607843137254902 0.19607843137254902 1 1"/>
    <material name="mbs6/geom_mbs6_geom11_material" class="mbs6/" texrepeat="1 1" emission="0" specular="0.5" shininess="0.5" reflectance="0" rgba="0.19607843137254902 0.19607843137254902 1 1"/>
    <material name="mbs6/geom_mbs6_geom12_material" class="mbs6/" texrepeat="1 1" emission="0" specular="0.5" shininess="0.5" reflectance="0" rgba="0.19607843137254902 0.19607843137254902 1 1"/>
    <material name="mbs6/geom_mbs6_geom13_material" class="mbs6/" texrepeat="1 1" emission="0" specular="0.5" shininess="0.5" reflectance="0" rgba="0.19607843137254902 0.19607843137254902 1 1"/>
    <material name="mbs6/geom_mbs6_geom14_material" class="mbs6/" texrepeat="1 1" emission="0" specular="0.5" shininess="0.5" reflectance="0" rgba="0.19607843137254902 0.19607843137254902 1 1"/>
    <material name="mbs6/geom_mbs6_geom15_material" class="mbs6/" texrepeat="1 1" emission="0" specular="0.5" shininess="0.5" reflectance="0" rgba="0.19607843137254902 0.19607843137254902 1 1"/>
    <material name="mbs6/geom_mbs6_geom16_material" class="mbs6/" texrepeat="1 1" emission="0" specular="0.5" shininess="0.5" reflectance="0" rgba="0.19607843137254902 0.19607843137254902 1 1"/>
    <material name="mbs6/geom_mbs6_geom17_material" class="mbs6/" texrepeat="1 1" emission="0" specular="0.5" shininess="0.5" reflectance="0" rgba="0.19607843137254902 0.19607843137254902 1 1"/>
    <material name="mbs6/geom_mbs6_geom18_material" class="mbs6/" texrepeat="1 1" emission="0" specular="0.5" shininess="0.5" reflectance="0" rgba="0.19607843137254902 0.19607843137254902 1 1"/>
    <material name="mbs6/geom_mbs6_geom19_material" class="mbs6/" texrepeat="1 1" emission="0" specular="0.5" shininess="0.5" reflectance="0" rgba="0.19607843137254902 0.19607843137254902 1 1"/>
  </asset>
  <worldbody>
    <light name="//unnamed_light_0" class="/" directional="true" castshadow="false" pos="0 0 100" ambient="0.5 0.5 0.5"/>
    <body pos="0 0 0" quat="0 0 0 1" name="mbs0/"/>
    <geom name="//unnamed_geom_0" class="/" type="plane" size="10 10 1" material="heightmap_0_material" pos="0 0 0" quat="0 0 0 1"/>
    <body pos="0 0 0" quat="0 0 0 1" name="mbs1/">
      <freejoint name="mbs1/"/>
      <geom name="mbs1/mbs1_geom0" class="mbs1/" type="box" size="0.074999999999999997 0.074999999999999997 0.074999999999999997" material="mbs1/geom_mbs1_geom0_material"/>
    </body>
    <body pos="1 0 0" quat="0 0 0 1" name="mbs2/">
      <freejoint name="mbs2/"/>
      <geom name="mbs2/mbs2_geom0" class="mbs2/" type="box" size="0.074999999999999997 0.074999999999999997 0.074999999999999997" material="mbs2/geom_mbs2_geom0_material"/>
      <geom name="mbs2/mbs2_geom1" class="mbs2/" type="box" size="0.0089999999999999993 0.026499999999999999 0.0082945499999999995" material="mbs2/geom_mbs2_geom1_material" pos="0.084000000000000005 -0.029000000000000001 0.032000000000000001" quat="0.70710700000000004 -0.70710700000000004 0 0"/>
      <geom name="mbs2/mbs2_geom2" class="mbs2/" type="box" size="0.0089999999999999993 0.026499999999999999 0.0082945499999999995" material="mbs2/geom_mbs2_geom2_material" pos="-0.084000000000000005 0.029000000000000001 0.032000000000000001" quat="0 0 0.70710700000000004 -0.70710700000000004"/>
      <geom name="mbs2/mbs2_geom3" class="mbs2/" type="box" size="0.0089999999999999993 0.026499999999999999 0.0082945499999999995" material="mbs2/geom_mbs2_geom3_material" pos="0.029000000000000001 0.084000000000000005 0.032000000000000001" quat="0.5 -0.5 -0.5 0.5"/>
      <geom name="mbs2/mbs2_geom4" class="mbs2/" type="box" size="0.0089999999999999993 0.026499999999999999 0.0082945499999999995" material="mbs2/geom_mbs2_geom4_material" pos="-0.029000000000000001 -0.084000000000000005 0.032000000000000001" quat="0.5 -0.5 0.5 -0.5"/>
      <body name="mbs2/mbs2_link0" pos="0.109525 -0.029000000000000001 0.032000000000000001" quat="0.70710700000000004 -0.70710700000000004 0 0">
        <inertial pos="0.032186399999999997 0 0" quat="0 0.70710700000000004 0 0.70710700000000004" mass="0.099320000000000006" diaginertia="6.8264700000000004e-05 5.7461299999999998e-05 2.71227e-05"/>
        <joint name="mbs2/mbs2_joint0" class="mbs2/" pos="0 0 0" axis="0 1 0" range="-1.0471999999999999 1.0471999999999999" armature="0.002"/>
        <geom name="mbs2/mbs2_link0_geom0" class="mbs2/" type="box" size="0.029149999999999999 0.025600000000000001 0.01" material="mbs2/geom_mbs2_link0_geom0_material" pos="0.017999999999999999 0 0"/>
        <geom name="mbs2/mbs2_link0_geom1" class="mbs2/" type="box" size="0.001 0.026499999999999999 0.026499999999999999" material="mbs2/geom_mbs2_link0_geom1_material" pos="0.048149999999999998 0 0"/>
        <geom name="mbs2/mbs2_link0_geom2" class="mbs2/" type="box" size="0.0089999999999999993 0.026499999999999999 0.0082945499999999995" material="mbs2/geom_mbs2_link0_geom2_material" pos="0.05815 0 0" quat="0.70710700000000004 -0.70710700000000004 0 0"/>
        <body name="mbs2/mbs2_link0_link1" pos="0.083674999999999999 0 0" quat="0.70710700000000004 -0.70710700000000004 0 0">
          <inertial pos="0.032186399999999997 0 0" quat="0 0.70710700000000004 0 0.70710700000000004" mass="0.099320000000000006" diaginertia="6.8264700000000004e-05 5.7461299999999998e-05 2.71227e-05"/>
          <joint name="mbs2/mbs2_link0_joint1" class="mbs2/" pos="0 0 0" axis="0 1 0" range="-1.0471999999999999 1.0471999999999999" armature="0.002"/>
          <geom name="mbs2/mbs2_link0_link1_geom0" class="mbs2/" type="box" size="0.029149999999999999 0.025600000000000001 0.01" material="mbs2/geom_mbs2_link0_link1_geom0_material" pos="0.017999999999999999 0 0"/>
          <geom name="mbs2/mbs2_link0_link1_geom1" class="mbs2/" type="box" size="0.001 0.026499999999999999 0.026499999999999999" material="mbs2/geom_mbs2_link0_link1_geom1_material" pos="0.048149999999999998 0 0"/>
          <geom name="mbs2/mbs2_link0_link1_geom2" class="mbs2/" type="box" size="0.0089999999999999993 0.026499999999999999 0.0082945499999999995" material="mbs2/geom_mbs2_link0_link1_geom2_material" pos="0.05815 0 0" quat="0.70710700000000004 -0.70710700000000004 0 0"/>
          <body name="mbs2/mbs2_link0_link1_link1" pos="0.083674999999999999 0 0" quat="0.70710700000000004 -0.70710700000000004 0 0">
            <inertial pos="0.032186399999999997 0 0" quat="0 0.70710700000000004 0 0.70710700000000004" mass="0.099320000000000006" diaginertia="6.8264700000000004e-05 5.7461299999999998e-05 2.71227e-05"/>
            <joint name="mbs2/mbs2_link0_link1_joint1" class="mbs2/" pos="0 0 0" axis="0 1 0" range="-1.0471999999999999 1.0471999999999999" armature="0.002"/>
            <geom name="mbs2/mbs2_link0_link1_link1_geom0" class="mbs2/" type="box" size="0.029149999999999999 0.025600000000000001 0.01" material="mbs2/geom_mbs2_link0_link1_link1_geom0_material" pos="0.017999999999999999 0 0"/>
            <geom name="mbs2/mbs2_link0_link1_link1_geom1" class="mbs2/" type="box" size="0.001 0.026499999999999999 0.026499999999999999" material="mbs2/geom_mbs2_link0_link1_link1_geom1_material" pos="0.048149999999999998 0 0"/>
            <geom name="mbs2/mbs2_link0_link1_link1_geom2" class="mbs2/" type="box" size="0.0089999999999999993 0.026499999999999999 0.0082945499999999995" material="mbs2/geom_mbs2_link0_link1_link1_geom2_material" pos="0.05815 0 0" quat="0.70710700000000004 -0.70710700000000004 0 0"/>
            <body name="mbs2/mbs2_link0_link1_link1_link1" pos="0.083674999999999999 0 0" quat="0.70710700000000004 -0.70710700000000004 0 0">
              <inertial pos="0.032186399999999997 0 0" quat="0 0.70710700000000004 0 0.70710700000000004" mass="0.099320000000000006" diaginertia="6.8264700000000004e-05 5.7461299999999998e-05 2.71227e-05"/>
              <joint name="mbs2/mbs2_link0_link1_link1_joint1" class="mbs2/" pos="0 0 0" axis="0 1 0" range="-1.0471999999999999 1.0471999999999999" armature="0.002"/>
              <geom name="mbs2/mbs2_link0_link1_link1_link1_geom0" class="mbs2/" type="box" size="0.029149999999999999 0.025600000000000001 0.01" material="mbs2/geom_mbs2_link0_link1_link1_link1_geom0_material" pos="0.017999999999999999 0 0"/>
              <geom name="mbs2/mbs2_link0_link1_link1_link1_geom1" class="mbs2/" type="box" size="0.001 0.026499999999999999 0.026499999999999999" material="mbs2/geom_mbs2_link0_link1_link1_link1_geom1_material" pos="0.048149999999999998 0 0"/>
              <geom name="mbs2/mbs2_link0_link1_link1_link1_geom2" class="mbs2/" type="box" size="0.0089999999999999993 0.026499999999999999 0.0082945499999999995" material="mbs2/geom_mbs2_link0_link1_link1_link1_geom2_material" pos="0.05815 0 0" quat="0.70710700000000004 -0.70710700000000004 0 0"/>
              <body name="mbs2/mbs2_link0_link1_link1_link1_link1" pos="0.083674999999999999 0 0" quat="0.70710700000000004 -0.70710700000000004 0 0">
                <inertial pos="0.027081299999999999 0 0" quat="0 0.70710700000000004 0 0.70710700000000004" mass="0.083000000000000004" diaginertia="5.0839199999999999e-05 4.0102199999999997e-05 2.6307799999999999e-05"/>
                <joint name="mbs2/mbs2_link0_link1_link1_link1_joint1" class="mbs2/" pos="0 0 0" axis="0 1 0" range="-1.0471999999999999 1.0471999999999999" armature="0.002"/>
                <geom name="mbs2/mbs2_link0_link1_link1_link1_link1_geom0" class="mbs2/" type="box" size="0.029149999999999999 0.025600000000000001 0.01" material="mbs2/geom_mbs2_link0_link1_link1_link1_link1_geom0_material" pos="0.017999999999999999 0 0"/>
                <geom name="mbs2/mbs2_link0_link1_link1_link1_link1_geom1" class="mbs2/" type="box" size="0.001 0.026499999999999999 0.026499999999999999" material="mbs2/geom_mbs2_link0_link1_link1_link1_link1_geom1_material" pos="0.048149999999999998 0 0"/>
              </body>
            </body>
          </body>
        </body>
      </body>
      <body name="mbs2/mbs2_link1" pos="-0.109525 0.029000000000000001 0.032000000000000001" quat="0 0 0.70710700000000004 -0.70710700000000004">
        <inertial pos="0.032186399999999997 0 0" quat="0 0.70710700000000004 0 0.70710700000000004" mass="0.099320000000000006" diaginertia="6.8264700000000004e-05 5.7461299999999998e-05 2.71227e-05"/>
        <joint name="mbs2/mbs2_joint1" class="mbs2/" pos="0 0 0" axis="0 1 0" range="-1.0471999999999999 1.0471999999999999" armature="0.002"/>
        <geom name="mbs2/mbs2_link1_geom0" class="mbs2/" type="box" size="0.029149999999999999 0.025600000000000001 0.01" material="mbs2/geom_mbs2_link1_geom0_material" pos="0.017999999999999999 0 0"/>
        <geom name="mbs2/mbs2_link1_geom1" class="mbs2/" type="box" size="0.001 0.026499999999999999 0.026499999999999999" material="mbs2/geom_mbs2_link1_geom1_material" pos="0.048149999999999998 0 0"/>
        <geom name="mbs2/mbs2_link1_geom2" class="mbs2/" type="box" size="0.0089999999999999993 0.026499999999999999 0.0082945499999999995" material="mbs2/geom_mbs2_link1_geom2_material" pos="0.05815 0 0" quat="0.70710700000000004 -0.70710700000000004 0 0"/>
        <body name="mbs2/mbs2_link1_link1" pos="0.083674999999999999 0 0" quat="0.70710700000000004 -0.70710700000000004 0 0">
          <inertial pos="0.032186399999999997 0 0" quat="0 0.70710700000000004 0 0.70710700000000004" mass="0.099320000000000006" diaginertia="6.8264700000000004e-05 5.7461299999999998e-05 2.71227e-05"/>
          <joint name="mbs2/mbs2_link1_joint1" class="mbs2/" pos="0 0 0" axis="0 1 0" range="-1.0471999999999999 1.0471999999999999" armature="0.002"/>
          <geom name="mbs2/mbs2_link1_link1_geom0" class="mbs2/" type="box" size="0.029149999999999999 0.025600000000000001 0.01" material="mbs2/geom_mbs2_link1_link1_geom0_material" pos="0.017999999999999999 0 0"/>
          <geom name="mbs2/mbs2_link1_link1_geom1" class="mbs2/" type="box" size="0.001 0.026499999999999999 0.026499999999999999" material="mbs2/geom_mbs2_link1_link1_geom1_material" pos="0.048149999999999998 0 0"/>
          <geom name="mbs2/mbs2_link1_link1_geom2" class="mbs2/" type="box" size="0.0089999999999999993 0.026499999999999999 0.0082945499999999995" material="mbs2/geom_mbs2_link1_link1_geom2_material" pos="0.05815 0 0" quat="0.70710700000000004 -0.70710700000000004 0 0"/>
          <body name="mbs2/mbs2_link1_link1_link1" pos="0.083674999999999999 0 0" quat="0.70710700000000004 -0.70710700000000004 0 0">
            <inertial pos="0.032186399999999997 0 0" quat="0 0.70710700000000004 0 0.70710700000000004" mass="0.099320000000000006" diaginertia="6.8264700000000004e-05 5.7461299999999998e-05 2.71227e-05"/>
            <joint name="mbs2/mbs2_link1_link1_joint1" class="mbs2/" pos="0 0 0" axis="0 1 0" range="-1.0471999999999999 1.0471999999999999" armature="0.002"/>
            <geom name="mbs2/mbs2_link1_link1_link1_geom0" class="mbs2/" type="box" size="0.029149999999999999 0.025600000000000001 0.01" material="mbs2/geom_mbs2_link1_link1_link1_geom0_material" pos="0.017999999999999999 0 0"/>
            <geom name="mbs2/mbs2_link1_link1_link1_geom1" class="mbs2/" type="box" size="0.001 0.026499999999999999 0.026499999999999999" material="mbs2/geom_mbs2_link1_link1_link1_geom1_material" pos="0.048149999999999998 0 0"/>
            <geom name="mbs2/mbs2_link1_link1_link1_geom2" class="mbs2/" type="box" size="0.0089999999999999993 0.026499999999999999 0.0082945499999999995" material="mbs2/geom_mbs2_link1_link1_link1_geom2_material" pos="0.05815 0 0" quat="0.70710700000000004 -0.70710700000000004 0 0"/>
            <body name="mbs2/mbs2_link1_link1_link1_link1" pos="0.083674999999999999 0 0" quat="0.70710700000000004 -0.70710700000000004 0 0">
              <inertial pos="0.032186399999999997 0 0" quat="0 0.70710700000000004 0 0.70710700000000004" mass="0.099320000000000006" diaginertia="6.8264700000000004e-05 5.7461299999999998e-05 2.71227e-05"/>
              <joint name="mbs2/mbs2_link1_link1_link1_joint1" class="mbs2/" pos="0 0 0" axis="0 1 0" range="-1.0471999999999999 1.0471999999999999" armature="0.002"/>
              <geom name="mbs2/mbs2_link1_link1_link1_link1_geom0" class="mbs2/" type="box" size="0.029149999999999999 0.025600000000000001 0.01" material="mbs2/geom_mbs2_link1_link1_link1_link1_geom0_material" pos="0.017999999999999999 0 0"/>
              <geom name="mbs2/mbs2_link1_link1_link1_link1_geom1" class="mbs2/" type="box" size="0.001 0.026499999999999999 0.026499999999999999" material="mbs2/geom_mbs2_link1_link1_link1_link1_geom1_material" pos="0.048149999999999998 0 0"/>
              <geom name="mbs2/mbs2_link1_link1_link1_link1_geom2" class="mbs2/" type="box" size="0.0089999999999999993 0.026499999999999999 0.0082945499999999995" material="mbs2/geom_mbs2_link1_link1_link1_link1_geom2_material" pos="0.05815 0 0" quat="0.70710700000000004 -0.70710700000000004 0 0"/>
              <body name="mbs2/mbs2_link1_link1_link1_link1_link1" pos="0.083674999999999999 0 0" quat="0.70710700000000004 -0.70710700000000004 0 0">
                <inertial pos="0.027081299999999999 0 0" quat="0 0.70710700000000004 0 0.70710700000000004" mass="0.083000000000000004" diaginertia="5.0839199999999999e-05 4.0102199999999997e-05 2.6307799999999999e-05"/>
                <joint name="mbs2/mbs2_link1_link1_link1_link1_joint1" class="mbs2/" pos="0 0 0" axis="0 1 0" range="-1.0471999999999999 1.0471999999999999" armature="0.002"/>
                <geom name="mbs2/mbs2_link1_link1_link1_link1_link1_geom0" class="mbs2/" type="box" size="0.029149999999999999 0.025600000000000001 0.01" material="mbs2/geom_mbs2_link1_link1_link1_link1_link1_geom0_material" pos="0.017999999999999999 0 0"/>
                <geom name="mbs2/mbs2_link1_link1_link1_link1_link1_geom1" class="mbs2/" type="box" size="0.001 0.026499999999999999 0.026499999999999999" material="mbs2/geom_mbs2_link1_link1_link1_link1_link1_geom1_material" pos="0.048149999999999998 0 0"/>
              </body>
            </body>
          </body>
        </body>
      </body>
      <body name="mbs2/mbs2_link2" pos="0.029000000000000001 0.109525 0.032000000000000001" quat="0.5 -0.5 -0.5 0.5">
        <inertial pos="0.032186399999999997 0 0" quat="0 0.70710700000000004 0 0.70710700000000004" mass="0.099320000000000006" diaginertia="6.8264700000000004e-05 5.7461299999999998e-05 2.71227e-05"/>
        <joint name="mbs2/mbs2_joint2" class="mbs2/" pos="0 0 0" axis="0 1 0" range="-1.0471999999999999 1.0471999999999999" armature="0.002"/>
        <geom name="mbs2/mbs2_link2_geom0" class="mbs2/" type="box" size="0.029149999999999999 0.025600000000000001 0.01" material="mbs2/geom_mbs2_link2_geom0_material" pos="0.017999999999999999 0 0"/>
        <geom name="mbs2/mbs2_link2_geom1" class="mbs2/" type="box" size="0.001 0.026499999999999999 0.026499999999999999" material="mbs2/geom_mbs2_link2_geom1_material" pos="0.048149999999999998 0 0"/>
        <geom name="mbs2/mbs2_link2_geom2" class="mbs2/" type="box" size="0.0089999999999999993 0.026499999999999999 0.0082945499999999995" material="mbs2/geom_mbs2_link2_geom2_material" pos="0.05815 0 0" quat="0.70710700000000004 -0.70710700000000004 0 0"/>
        <body name="mbs2/mbs2_link2_link1" pos="0.083674999999999999 0 0" quat="0.70710700000000004 -0.70710700000000004 0 0">
          <inertial pos="0.032186399999999997 0 0" quat="0 0.70710700000000004 0 0.70710700000000004" mass="0.099320000000000006" diaginertia="6.8264700000000004e-05 5.7461299999999998e-05 2.71227e-05"/>
          <joint name="mbs2/mbs2_link2_joint1" class="mbs2/" pos="0 0 0" axis="0 1 0" range="-1.0471999999999999 1.0471999999999999" armature="0.002"/>
          <geom name="mbs2/mbs2_link2_link1_geom0" class="mbs2/" type="box" size="0.029149999999999999 0.025600000000000001 0.01" material="mbs2/geom_mbs2_link2_link1_geom0_material" pos="0.017999999999999999 0 0"/>
          <geom name="mbs2/mbs2_link2_link1_geom1" class="mbs2/" type="box" size="0.001 0.026499999999999999 0.026499999999999999" material="mbs2/geom_mbs2_link2_link1_geom1_material" pos="0.048149999999999998 0 0"/>
          <geom name="mbs2/mbs2_link2_link1_geom2" class="mbs2/" type="box" size="0.0089999999999999993 0.026499999999999999 0.0082945499999999995" material="mbs2/geom_mbs2_link2_link1_geom2_material" pos="0.05815 0 0" quat="0.70710700000000004 -0.70710700000000004 0 0"/>
          <body name="mbs2/mbs2_link2_link1_link1" pos="0.083674999999999999 0 0" quat="0.70710700000000004 -0.70710700000000004 0 0">
            <inertial pos="0.032186399999999997 0 0" quat="0 0.70710700000000004 0 0.70710700000000004" mass="0.099320000000000006" diaginertia="6.8264700000000004e-05 5.7461299999999998e-05 2.71227e-05"/>
            <joint name="mbs2/mbs2_link2_link1_joint1" class="mbs2/" pos="0 0 0" axis="0 1 0" range="-1.0471999999999999 1.0471999999999999" armature="0.002"/>
            <geom name="mbs2/mbs2_link2_link1_link1_geom0" class="mbs2/" type="box" size="0.029149999999999999 0.025600000000000001 0.01" material="mbs2/geom_mbs2_link2_link1_link1_geom0_material" pos="0.017999999999999999 0 0"/>
            <geom name="mbs2/mbs2_link2_link1_link1_geom1" class="mbs2/" type="box" size="0.001 0.026499999999999999 0.026499999999999999" material="mbs2/geom_mbs2_link2_link1_link1_geom1_material" pos="0.048149999999999998 0 0"/>
            <geom name="mbs2/mbs2_link2_link1_link1_geom2" class="mbs2/" type="box" size="0.0089999999999999993 0.026499999999999999 0.0082945499999999995" material="mbs2/geom_mbs2_link2_link1_link1_geom2_material" pos="0.05815 0 0" quat="0.70710700000000004 -0.70710700000000004 0 0"/>
            <body name="mbs2/mbs2_link2_link1_link1_link1" pos="0.083674999999999999 0 0" quat="0.70710700000000004 -0.70710700000000004 0 0">
              <inertial pos="0.027081299999999999 0 0" quat="0 0.70710700000000004 0 0.70710700000000004" mass="0.083000000000000004" diaginertia="5.0839199999999999e-05 4.0102199999999997e-05 2.6307799999999999e-05"/>
              <joint name="mbs2/mbs2_link2_link1_link1_joint1" class="mbs2/" pos="0 0 0" axis="0 1 0" range="-1.0471999999999999 1.0471999999999999" armature="0.002"/>
              <geom name="mbs2/mbs2_link2_link1_link1_link1_geom0" class="mbs2/" type="box" size="0.029149999999999999 0.025600000000000001 0.01" material="mbs2/geom_mbs2_link2_link1_link1_link1_geom0_material" pos="0.017999999999999999 0 0"/>
              <geom name="mbs2/mbs2_link2_link1_link1_link1_geom1" class="mbs2/" type="box" size="0.001 0.026499999999999999 0.026499999999999999" material="mbs2/geom_mbs2_link2_link1_link1_link1_geom1_material" pos="0.048149999999999998 0 0"/>
            </body>
          </body>
        </body>
      </body>
      <body name="mbs2/mbs2_link3" pos="-0.029000000000000001 -0.109525 0.032000000000000001" quat="0.5 -0.5 0.5 -0.5">
        <inertial pos="0.032186399999999997 0 0" quat="0 0.70710700000000004 0 0.70710700000000004" mass="0.099320000000000006" diaginertia="6.8264700000000004e-05 5.7461299999999998e-05 2.71227e-05"/>
        <joint name="mbs2/mbs2_joint3" class="mbs2/" pos="0 0 0" axis="0 1 0" range="-1.0471999999999999 1.0471999999999999" armature="0.002"/>
        <geom name="mbs2/mbs2_link3_geom0" class="mbs2/" type="box" size="0.029149999999999999 0.025600000000000001 0.01" material="mbs2/geom_mbs2_link3_geom0_material" pos="0.017999999999999999 0 0"/>
        <geom name="mbs2/mbs2_link3_geom1" class="mbs2/" type="box" size="0.001 0.026499999999999999 0.026499999999999999" material="mbs2/geom_mbs2_link3_geom1_material" pos="0.048149999999999998 0 0"/>
        <geom name="mbs2/mbs2_link3_geom2" class="mbs2/" type="box" size="0.0089999999999999993 0.026499999999999999 0.0082945499999999995" material="mbs2/geom_mbs2_link3_geom2_material" pos="0.05815 0 0" quat="0.70710700000000004 -0.70710700000000004 0 0"/>
        <body name="mbs2/mbs2_link3_link1" pos="0.083674999999999999 0 0" quat="0.70710700000000004 -0.70710700000000004 0 0">
          <inertial pos="0.032186399999999997 0 0" quat="0 0.70710700000000004 0 0.70710700000000004" mass="0.099320000000000006" diaginertia="6.8264700000000004e-05 5.7461299999999998e-05 2.71227e-05"/>
          <joint name="mbs2/mbs2_link3_joint1" class="mbs2/" pos="0 0 0" axis="0 1 0" range="-1.0471999999999999 1.0471999999999999" armature="0.002"/>
          <geom name="mbs2/mbs2_link3_link1_geom0" class="mbs2/" type="box" size="0.029149999999999999 0.025600000000000001 0.01" material="mbs2/geom_mbs2_link3_link1_geom0_material" pos="0.017999999999999999 0 0"/>
          <geom name="mbs2/mbs2_link3_link1_geom1" class="mbs2/" type="box" size="0.001 0.026499999999999999 0.026499999999999999" material="mbs2/geom_mbs2_link3_link1_geom1_material" pos="0.048149999999999998 0 0"/>
          <geom name="mbs2/mbs2_link3_link1_geom2" class="mbs2/" type="box" size="0.0089999999999999993 0.026499999999999999 0.0082945499999999995" material="mbs2/geom_mbs2_link3_link1_geom2_material" pos="0.05815 0 0" quat="0.70710700000000004 -0.70710700000000004 0 0"/>
          <body name="mbs2/mbs2_link3_link1_link1" pos="0.083674999999999999 0 0" quat="0.70710700000000004 -0.70710700000000004 0 0">
            <inertial pos="0.032186399999999997 0 0" quat="0 0.70710700000000004 0 0.70710700000000004" mass="0.099320000000000006" diaginertia="6.8264700000000004e-05 5.7461299999999998e-05 2.71227e-05"/>
            <joint name="mbs2/mbs2_link3_link1_joint1" class="mbs2/" pos="0 0 0" axis="0 1 0" range="-1.0471999999999999 1.0471999999999999" armature="0.002"/>
            <geom name="mbs2/mbs2_link3_link1_link1_geom0" class="mbs2/" type="box" size="0.029149999999999999 0.025600000000000001 0.01" material="mbs2/geom_mbs2_link3_link1_link1_geom0_material" pos="0.017999999999999999 0 0"/>
            <geom name="mbs2/mbs2_link3_link1_link1_geom1" class="mbs2/" type="box" size="0.001 0.026499999999999999 0.026499999999999999" material="mbs2/geom_mbs2_link3_link1_link1_geom1_material" pos="0.048149999999999998 0 0"/>
            <geom name="mbs2/mbs2_link3_link1_link1_geom2" class="mbs2/" type="box" size="0.0089999999999999993 0.026499999999999999 0.0082945499999999995" material="mbs2/geom_mbs2_link3_link1_link1_geom2_material" pos="0.05815 0 0" quat="0.70710700000000004 -0.70710700000000004 0 0"/>
            <body name="mbs2/mbs2_link3_link1_link1_link1" pos="0.083674999999999999 0 0" quat="0.70710700000000004 -0.70710700000000004 0 0">
              <inertial pos="0.032186399999999997 0 0" quat="0 0.70710700000000004 0 0.70710700000000004" mass="0.099320000000000006" diaginertia="6.8264700000000004e-05 5.7461299999999998e-05 2.71227e-05"/>
              <joint name="mbs2/mbs2_link3_link1_link1_joint1" class="mbs2/" pos="0 0 0" axis="0 1 0" range="-1.0471999999999999 1.0471999999999999" armature="0.002"/>
              <geom name="mbs2/mbs2_link3_link1_link1_link1_geom0" class="mbs2/" type="box" size="0.029149999999999999 0.025600000000000001 0.01" material="mbs2/geom_mbs2_link3_link1_link1_link1_geom0_material" pos="0.017999999999999999 0 0"/>
              <geom name="mbs2/mbs2_link3_link1_link1_link1_geom1" class="mbs2/" type="box" size="0.001 0.026499999999999999 0.026499999999999999" material="mbs2/geom_mbs2_link3_link1_link1_link1_geom1_material" pos="0.048149999999999998 0 0"/>
              <geom name="mbs2/mbs2_link3_link1_link1_link1_geom2" class="mbs2/" type="box" size="0.0089999999999999993 0.026499999999999999 0.0082945499999999995" material="mbs2/geom_mbs2_link3_link1_link1_link1_geom2_material" pos="0.05815 0 0" quat="0.70710700000000004 -0.70710700000000004 0 0"/>
              <body name="mbs2/mbs2_link3_link1_link1_link1_link1" pos="0.083674999999999999 0 0" quat="0.70710700000000004 -0.70710700000000004 0 0">
                <inertial pos="0.027081299999999999 0 0" quat="0 0.70710700000000004 0 0.70710700000000004" mass="0.083000000000000004" diaginertia="5.0839199999999999e-05 4.0102199999999997e-05 2.6307799999999999e-05"/>
                <joint name="mbs2/mbs2_link3_link1_link1_link1_joint1" class="mbs2/" pos="0 0 0" axis="0 1 0" range="-1.0471999999999999 1.0471999999999999" armature="0.002"/>
                <geom name="mbs2/mbs2_link3_link1_link1_link1_link1_geom0" class="mbs2/" type="box" size="0.029149999999999999 0.025600000000000001 0.01" material="mbs2/geom_mbs2_link3_link1_link1_link1_link1_geom0_material" pos="0.017999999999999999 0 0"/>
                <geom name="mbs2/mbs2_link3_link1_link1_link1_link1_geom1" class="mbs2/" type="box" size="0.001 0.026499999999999999 0.026499999999999999" material="mbs2/geom_mbs2_link3_link1_link1_link1_link1_geom1_material" pos="0.048149999999999998 0 0"/>
              </body>
            </body>
          </body>
        </body>
      </body>
    </body>
    <body pos="2 0 0" quat="0 0 0 1" name="mbs3/">
      <freejoint name="mbs3/"/>
      <geom name="mbs3/mbs3_geom0" class="mbs3/" type="box" size="0.074999999999999997 0.074999999999999997 0.074999999999999997" material="mbs3/geom_mbs3_geom0_material"/>
      <geom name="mbs3/mbs3_geom1" class="mbs3/" type="box" size="0.0089999999999999993 0.026499999999999999 0.0082945499999999995" material="mbs3/geom_mbs3_geom1_material" pos="0.084000000000000005 -0.029000000000000001 0.032000000000000001" quat="0.70710700000000004 -0.70710700000000004 0 0"/>
      <geom name="mbs3/mbs3_geom2" class="mbs3/" type="box" size="0.0089999999999999993 0.026499999999999999 0.0082945499999999995" material="mbs3/geom_mbs3_geom2_material" pos="-0.084000000000000005 0.029000000000000001 0.032000000000000001" quat="0 0 0.70710700000000004 -0.70710700000000004"/>
      <geom name="mbs3/mbs3_geom3" class="mbs3/" type="box" size="0.0089999999999999993 0.026499999999999999 0.0082945499999999995" material="mbs3/geom_mbs3_geom3_material" pos="0.029000000000000001 0.084000000000000005 0.032000000000000001" quat="0.5 -0.5 -0.5 0.5"/>
      <geom name="mbs3/mbs3_geom4" class="mbs3/" type="box" size="0.0089999999999999993 0.026499999999999999 0.0082945499999999995" material="mbs3/geom_mbs3_geom4_material" pos="-0.029000000000000001 -0.084000000000000005 0.032000000000000001" quat="0.5 -0.5 0.5 -0.5"/>
      <body name="mbs3/mbs3_link0" pos="0.109525 -0.029000000000000001 0.032000000000000001" quat="0.70710700000000004 -0.70710700000000004 0 0">
        <inertial pos="0.032186399999999997 0 0" quat="0 0.70710700000000004 0 0.70710700000000004" mass="0.099320000000000006" diaginertia="6.8264700000000004e-05 5.7461299999999998e-05 2.71227e-05"/>
        <joint name="mbs3/mbs3_joint0" class="mbs3/" pos="0 0 0" axis="0 1 0" range="-1.0471999999999999 1.0471999999999999" armature="0.002"/>
        <geom name="mbs3/mbs3_link0_geom0" class="mbs3/" type="box" size="0.029149999999999999 0.025600000000000001 0.01" material="mbs3/geom_mbs3_link0_geom0_material" pos="0.017999999999999999 0 0"/>
        <geom name="mbs3/mbs3_link0_geom1" class="mbs3/" type="box" size="0.001 0.026499999999999999 0.026499999999999999" material="mbs3/geom_mbs3_link0_geom1_material" pos="0.048149999999999998 0 0"/>
        <geom name="mbs3/mbs3_link0_geom2" class="mbs3/" type="box" size="0.0089999999999999993 0.026499999999999999 0.0082945499999999995" material="mbs3/geom_mbs3_link0_geom2_material" pos="0.05815 0 0" quat="0.70710700000000004 -0.70710700000000004 0 0"/>
        <body name="mbs3/mbs3_link0_link1" pos="0.083674999999999999 0 0" quat="0.70710700000000004 -0.70710700000000004 0 0">
          <inertial pos="0.032186399999999997 0 0" quat="0 0.70710700000000004 0 0.70710700000000004" mass="0.099320000000000006" diaginertia="6.8264700000000004e-05 5.7461299999999998e-05 2.71227e-05"/>
          <joint name="mbs3/mbs3_link0_joint1" class="mbs3/" pos="0 0 0" axis="0 1 0" range="-1.0471999999999999 1.0471999999999999" armature="0.002"/>
          <geom name="mbs3/mbs3_link0_link1_geom0" class="mbs3/" type="box" size="0.029149999999999999 0.025600000000000001 0.01" material="mbs3/geom_mbs3_link0_link1_geom0_material" pos="0.017999999999999999 0 0"/>
          <geom name="mbs3/mbs3_link0_link1_geom1" class="mbs3/" type="box" size="0.001 0.026499999999999999 0.026499999999999999" material="mbs3/geom_mbs3_link0_link1_geom1_material" pos="0.048149999999999998 0 0"/>
          <geom name="mbs3/mbs3_link0_link1_geom2" class="mbs3/" type="box" size="0.0089999999999999993 0.026499999999999999 0.0082945499999999995" material="mbs3/geom_mbs3_link0_link1_geom2_material" pos="0.05815 0 0" quat="0.70710700000000004 -0.70710700000000004 0 0"/>
          <body name="mbs3/mbs3_link0_link1_link1" pos="0.083674999999999999 0 0" quat="0.70710700000000004 -0.70710700000000004 0 0">
            <inertial pos="0.032186399999999997 0 0" quat="0 0.70710700000000004 0 0.70710700000000004" mass="0.099320000000000006" diaginertia="6.8264700000000004e-05 5.7461299999999998e-05 2.71227e-05"/>
            <joint name="mbs3/mbs3_link0_link1_joint1" class="mbs3/" pos="0 0 0" axis="0 1 0" range="-1.0471999999999999 1.0471999999999999" armature="0.002"/>
            <geom name="mbs3/mbs3_link0_link1_link1_geom0" class="mbs3/" type="box" size="0.029149999999999999 0.025600000000000001 0.01" material="mbs3/geom_mbs3_link0_link1_link1_geom0_material" pos="0.017999999999999999 0 0"/>
            <geom name="mbs3/mbs3_link0_link1_link1_geom1" class="mbs3/" type="box" size="0.001 0.026499999999999999 0.026499999999999999" material="mbs3/geom_mbs3_link0_link1_link1_geom1_material" pos="0.048149999999999998 0 0"/>
            <geom name="mbs3/mbs3_link0_link1_link1_geom2" class="mbs3/" type="box" size="0.0089999999999999993 0.026499999999999999 0.0082945499999999995" material="mbs3/geom_mbs3_link0_link1_link1_geom2_material" pos="0.05815 0 0" quat="0.70710700000000004 -0.70710700000000004 0 0"/>
            <body name="mbs3/mbs3_link0_link1_link1_link1" pos="0.083674999999999999 0 0" quat="0.70710700000000004 -0.70710700000000004 0 0">
              <inertial pos="0.032186399999999997 0 0" quat="0 0.70710700000000004 0 0.70710700000000004" mass="0.099320000000000006" diaginertia="6.8264700000000004e-05 5.7461299999999998e-05 2.71227e-05"/>
              <joint name="mbs3/mbs3_link0_link1_link1_joint1" class="mbs3/" pos="0 0 0" axis="0 1 0" range="-1.0471999999999999 1.0471999999999999" armature="0.002"/>
              <geom name="mbs3/mbs3_link0_link1_link1_link1_geom0" class="mbs3/" type="box" size="0.029149999999999999 0.025600000000000001 0.01" material="mbs3/geom_mbs3_link0_link1_link1_link1_geom0_material" pos="0.017999999999999999 0 0"/>
              <geom name="mbs3/mbs3_link0_link1_link1_link1_geom1" class="mbs3/" type="box" size="0.001 0.026499999999999999 0.026499999999999999" material="mbs3/geom_mbs3_link0_link1_link1_link1_geom1_material" pos="0.048149999999999998 0 0"/>
              <geom name="mbs3/mbs3_link0_link1_link1_link1_geom2" class="mbs3/" type="box" size="0.0089999999999999993 0.026499999999999999 0.0082945499999999995" material="mbs3/geom_mbs3_link0_link1_link1_link1_geom2_material" pos="0.05815 0 0" quat="0.70710700000000004 -0.70710700000000004 0 0"/>
              <body name="mbs3/mbs3_link0_link1_link1_link1_link1" pos="0.083674999999999999 0 0" quat="0.70710700000000004 -0.70710700000000004 0 0">
                <inertial pos="0.027081299999999999 0 0" quat="0 0.70710700000000004 0 0.70710700000000004" mass="0.083000000000000004" diaginertia="5.0839199999999999e-05 4.0102199999999997e-05 2.6307799999999999e-05"/>
                <joint name="mbs3/mbs3_link0_link1_link1_link1_joint1" class="mbs3/" pos="0 0 0" axis="0 1 0" range="-1.0471999999999999 1.0471999999999999" armature="0.002"/>
                <geom name="mbs3/mbs3_link0_link1_link1_link1_link1_geom0" class="mbs3/" type="box" size="0.029149999999999999 0.025600000000000001 0.01" material="mbs3/geom_mbs3_link0_link1_link1_link1_link1_geom0_material" pos="0.017999999999999999 0 0"/>
                <geom name="mbs3/mbs3_link0_link1_link1_link1_link1_geom1" class="mbs3/" type="box" size="0.001 0.026499999999999999 0.026499999999999999" material="mbs3/geom_mbs3_link0_link1_link1_link1_link1_geom1_material" pos="0.048149999999999998 0 0"/>
              </body>
            </body>
          </body>
        </body>
      </body>
      <body name="mbs3/mbs3_link1" pos="-0.109525 0.029000000000000001 0.032000000000000001" quat="0 0 0.70710700000000004 -0.70710700000000004">
        <inertial pos="0.032186399999999997 0 0" quat="0 0.70710700000000004 0 0.70710700000000004" mass="0.099320000000000006" diaginertia="6.8264700000000004e-05 5.7461299999999998e-05 2.71227e-05"/>
        <joint name="mbs3/mbs3_joint1" class="mbs3/" pos="0 0 0" axis="0 1 0" range="-1.0471999999999999 1.0471999999999999" armature="0.002"/>
        <geom name="mbs3/mbs3_link1_geom0" class="mbs3/" type="box" size="0.029149999999999999 0.025600000000000001 0.01" material="mbs3/geom_mbs3_link1_geom0_material" pos="0.017999999999999999 0 0"/>
        <geom name="mbs3/mbs3_link1_geom1" class="mbs3/" type="box" size="0.001 0.026499999999999999 0.026499999999999999" material="mbs3/geom_mbs3_link1_geom1_material" pos="0.048149999999999998 0 0"/>
        <geom name="mbs3/mbs3_link1_geom2" class="mbs3/" type="box" size="0.0089999999999999993 0.026499999999999999 0.0082945499999999995" material="mbs3/geom_mbs3_link1_geom2_material" pos="0.05815 0 0" quat="0.70710700000000004 -0.70710700000000004 0 0"/>
        <body name="mbs3/mbs3_link1_link1" pos="0.083674999999999999 0 0" quat="0.70710700000000004 -0.70710700000000004 0 0">
          <inertial pos="0.032186399999999997 0 0" quat="0 0.70710700000000004 0 0.70710700000000004" mass="0.099320000000000006" diaginertia="6.8264700000000004e-05 5.7461299999999998e-05 2.71227e-05"/>
          <joint name="mbs3/mbs3_link1_joint1" class="mbs3/" pos="0 0 0" axis="0 1 0" range="-1.0471999999999999 1.0471999999999999" armature="0.002"/>
          <geom name="mbs3/mbs3_link1_link1_geom0" class="mbs3/" type="box" size="0.029149999999999999 0.025600000000000001 0.01" material="mbs3/geom_mbs3_link1_link1_geom0_material" pos="0.017999999999999999 0 0"/>
          <geom name="mbs3/mbs3_link1_link1_geom1" class="mbs3/" type="box" size="0.001 0.026499999999999999 0.026499999999999999" material="mbs3/geom_mbs3_link1_link1_geom1_material" pos="0.048149999999999998 0 0"/>
          <geom name="mbs3/mbs3_link1_link1_geom2" class="mbs3/" type="box" size="0.0089999999999999993 0.026499999999999999 0.0082945499999999995" material="mbs3/geom_mbs3_link1_link1_geom2_material" pos="0.05815 0 0" quat="0.70710700000000004 -0.70710700000000004 0 0"/>
          <body name="mbs3/mbs3_link1_link1_link1" pos="0.083674999999999999 0 0" quat="0.70710700000000004 -0.70710700000000004 0 0">
            <inertial pos="0.032186399999999997 0 0" quat="0 0.70710700000000004 0 0.70710700000000004" mass="0.099320000000000006" diaginertia="6.8264700000000004e-05 5.7461299999999998e-05 2.71227e-05"/>
            <joint name="mbs3/mbs3_link1_link1_joint1" class="mbs3/" pos="0 0 0" axis="0 1 0" range="-1.0471999999999999 1.0471999999999999" armature="0.002"/>
            <geom name="mbs3/mbs3_link1_link1_link1_geom0" class="mbs3/" type="box" size="0.029149999999999999 0.025600000000000001 0.01" material="mbs3/geom_mbs3_link1_link1_link1_geom0_material" pos="0.017999999999999999 0 0"/>
            <geom name="mbs3/mbs3_link1_link1_link1_geom1" class="mbs3/" type="box" size="0.001 0.026499999999999999 0.026499999999999999" material="mbs3/geom_mbs3_link1_link1_link1_geom1_material" pos="0.048149999999999998 0 0"/>
            <geom name="mbs3/mbs3_link1_link1_link1_geom2" class="mbs3/" type="box" size="0.0089999999999999993 0.026499999999999999 0.0082945499999999995" material="mbs3/geom_mbs3_link1_link1_link1_geom2_material" pos="0.05815 0 0" quat="0.70710700000000004 -0.70710700000000004 0 0"/>
            <body name="mbs3/mbs3_link1_link1_link1_link1" pos="0.083674999999999999 0 0" quat="0.70710700000000004 -0.70710700000000004 0 0">
              <inertial pos="0.032186399999999997 0 0" quat="0 0.70710700000000004 0 0.70710700000000004" mass="0.099320000000000006" diaginertia="6.8264700000000004e-05 5.7461299999999998e-05 2.71227e-05"/>
              <joint name="mbs3/mbs3_link1_link1_link1_joint1" class="mbs3/" pos="0 0 0" axis="0 1 0" range="-1.0471999999999999 1.0471999999999999" armature="0.002"/>
              <geom name="mbs3/mbs3_link1_link1_link1_link1_geom0" class="mbs3/" type="box" size="0.029149999999999999 0.025600000000000001 0.01" material="mbs3/geom_mbs3_link1_link1_link1_link1_geom0_material" pos="0.017999999999999999 0 0"/>
              <geom name="mbs3/mbs3_link1_link1_link1_link1_geom1" class="mbs3/" type="box" size="0.001 0.026499999999999999 0.026499999999999999" material="mbs3/geom_mbs3_link1_link1_link1_link1_geom1_material" pos="0.048149999999999998 0 0"/>
              <geom name="mbs3/mbs3_link1_link1_link1_link1_geom2" class="mbs3/" type="box" size="0.0089999999999999993 0.026499999999999999 0.0082945499999999995" material="mbs3/geom_mbs3_link1_link1_link1_link1_geom2_material" pos="0.05815 0 0" quat="0.70710700000000004 -0.70710700000000004 0 0"/>
              <body name="mbs3/mbs3_link1_link1_link1_link1_link1" pos="0.083674999999999999 0 0" quat="0.70710700000000004 -0.70710700000000004 0 0">
                <inertial pos="0.027081299999999999 0 0" quat="0 0.70710700000000004 0 0.70710700000000004" mass="0.083000000000000004" diaginertia="5.0839199999999999e-05 4.0102199999999997e-05 2.6307799999999999e-05"/>
                <joint name="mbs3/mbs3_link1_link1_link1_link1_joint1" class="mbs3/" pos="0 0 0" axis="0 1 0" range="-1.0471999999999999 1.0471999999999999" armature="0.002"/>
                <geom name="mbs3/mbs3_link1_link1_link1_link1_link1_geom0" class="mbs3/" type="box" size="0.029149999999999999 0.025600000000000001 0.01" material="mbs3/geom_mbs3_link1_link1_link1_link1_link1_geom0_material" pos="0.017999999999999999 0 0"/>
                <geom name="mbs3/mbs3_link1_link1_link1_link1_link1_geom1" class="mbs3/" type="box" size="0.001 0.026499999999999999 0.026499999999999999" material="mbs3/geom_mbs3_link1_link1_link1_link1_link1_geom1_material" pos="0.048149999999999998 0 0"/>
              </body>
            </body>
          </body>
        </body>
      </body>
      <body name="mbs3/mbs3_link2" pos="0.029000000000000001 0.109525 0.032000000000000001" quat="0.5 -0.5 -0.5 0.5">
        <inertial pos="0.032186399999999997 0 0" quat="0 0.70710700000000004 0 0.70710700000000004" mass="0.099320000000000006" diaginertia="6.8264700000000004e-05 5.7461299999999998e-05 2.71227e-05"/>
        <joint name="mbs3/mbs3_joint2" class="mbs3/" pos="0 0 0" axis="0 1 0" range="-1.0471999999999999 1.0471999999999999" armature="0.002"/>
        <geom name="mbs3/mbs3_link2_geom0" class="mbs3/" type="box" size="0.029149999999999999 0.025600000000000001 0.01" material="mbs3/geom_mbs3_link2_geom0_material" pos="0.017999999999999999 0 0"/>
        <geom name="mbs3/mbs3_link2_geom1" class="mbs3/" type="box" size="0.001 0.026499999999999999 0.026499999999999999" material="mbs3/geom_mbs3_link2_geom1_material" pos="0.048149999999999998 0 0"/>
        <geom name="mbs3/mbs3_link2_geom2" class="mbs3/" type="box" size="0.0089999999999999993 0.026499999999999999 0.0082945499999999995" material="mbs3/geom_mbs3_link2_geom2_material" pos="0.05815 0 0" quat="0.70710700000000004 -0.70710700000000004 0 0"/>
        <body name="mbs3/mbs3_link2_link1" pos="0.083674999999999999 0 0" quat="0.70710700000000004 -0.70710700000000004 0 0">
          <inertial pos="0.032186399999999997 0 0" quat="0 0.70710700000000004 0 0.70710700000000004" mass="0.099320000000000006" diaginertia="6.8264700000000004e-05 5.7461299999999998e-05 2.71227e-05"/>
          <joint name="mbs3/mbs3_link2_joint1" class="mbs3/" pos="0 0 0" axis="0 1 0" range="-1.0471999999999999 1.0471999999999999" armature="0.002"/>
          <geom name="mbs3/mbs3_link2_link1_geom0" class="mbs3/" type="box" size="0.029149999999999999 0.025600000000000001 0.01" material="mbs3/geom_mbs3_link2_link1_geom0_material" pos="0.017999999999999999 0 0"/>
          <geom name="mbs3/mbs3_link2_link1_geom1" class="mbs3/" type="box" size="0.001 0.026499999999999999 0.026499999999999999" material="mbs3/geom_mbs3_link2_link1_geom1_material" pos="0.048149999999999998 0 0"/>
          <geom name="mbs3/mbs3_link2_link1_geom2" class="mbs3/" type="box" size="0.0089999999999999993 0.026499999999999999 0.0082945499999999995" material="mbs3/geom_mbs3_link2_link1_geom2_material" pos="0.05815 0 0" quat="0.70710700000000004 -0.70710700000000004 0 0"/>
          <body name="mbs3/mbs3_link2_link1_link1" pos="0.083674999999999999 0 0" quat="0.70710700000000004 -0.70710700000000004 0 0">
            <inertial pos="0.032186399999999997 0 0" quat="0 0.70710700000000004 0 0.70710700000000004" mass="0.099320000000000006" diaginertia="6.8264700000000004e-05 5.7461299999999998e-05 2.71227e-05"/>
            <joint name="mbs3/mbs3_link2_link1_joint1" class="mbs3/" pos="0 0 0" axis="0 1 0" range="-1.0471999999999999 1.0471999999999999" armature="0.002"/>
            <geom name="mbs3/mbs3_link2_link1_link1_geom0" class="mbs3/" type="box" size="0.029149999999999999 0.025600000000000001 0.01" material="mbs3/geom_mbs3_link2_link1_link1_geom0_material" pos="0.017999999999999999 0 0"/>
            <geom name="mbs3/mbs3_link2_link1_link1_geom1" class="mbs3/" type="box" size="0.001 0.026499999999999999 0.026499999999999999" material="mbs3/geom_mbs3_link2_link1_link1_geom1_material" pos="0.048149999999999998 0 0"/>
            <geom name="mbs3/mbs3_link2_link1_link1_geom2" class="mbs3/" type="box" size="0.0089999999999999993 0.026499999999999999 0.0082945499999999995" material="mbs3/geom_mbs3_link2_link1_link1_geom2_material" pos="0.05815 0 0" quat="0.70710700000000004 -0.70710700000000004 0 0"/>
            <body name="mbs3/mbs3_link2_link1_link1_link1" pos="0.083674999999999999 0 0" quat="0.70710700000000004 -0.70710700000000004 0 0">
              <inertial pos="0.027081299999999999 0 0" quat="0 0.70710700000000004 0 0.70710700000000004" mass="0.083000000000000004" diaginertia="5.0839199999999999e-05 4.0102199999999997e-05 2.6307799999999999e-05"/>
              <joint name="mbs3/mbs3_link2_link1_link1_joint1" class="mbs3/" pos="0 0 0" axis="0 1 0" range="-1.0471999999999999 1.0471999999999999" armature="0.002"/>
              <geom name="mbs3/mbs3_link2_link1_link1_link1_geom0" class="mbs3/" type="box" size="0.029149999999999999 0.025600000000000001 0.01" material="mbs3/geom_mbs3_link2_link1_link1_link1_geom0_material" pos="0.017999999999999999 0 0"/>
              <geom name="mbs3/mbs3_link2_link1_link1_link1_geom1" class="mbs3/" type="box" size="0.001 0.026499999999999999 0.026499999999999999" material="mbs3/geom_mbs3_link2_link1_link1_link1_geom1_material" pos="0.048149999999999998 0 0"/>
            </body>
          </body>
        </body>
      </body>
      <body name="mbs3/mbs3_link3" pos="-0.029000000000000001 -0.109525 0.032000000000000001" quat="0.5 -0.5 0.5 -0.5">
        <inertial pos="0.032186399999999997 0 0" quat="0 0.70710700000000004 0 0.70710700000000004" mass="0.099320000000000006" diaginertia="6.8264700000000004e-05 5.7461299999999998e-05 2.71227e-05"/>
        <joint name="mbs3/mbs3_joint3" class="mbs3/" pos="0 0 0" axis="0 1 0" range="-1.0471999999999999 1.0471999999999999" armature="0.002"/>
        <geom name="mbs3/mbs3_link3_geom0" class="mbs3/" type="box" size="0.029149999999999999 0.025600000000000001 0.01" material="mbs3/geom_mbs3_link3_geom0_material" pos="0.017999999999999999 0 0"/>
        <geom name="mbs3/mbs3_link3_geom1" class="mbs3/" type="box" size="0.001 0.026499999999999999 0.026499999999999999" material="mbs3/geom_mbs3_link3_geom1_material" pos="0.048149999999999998 0 0"/>
        <geom name="mbs3/mbs3_link3_geom2" class="mbs3/" type="box" size="0.0089999999999999993 0.026499999999999999 0.0082945499999999995" material="mbs3/geom_mbs3_link3_geom2_material" pos="0.05815 0 0" quat="0.70710700000000004 -0.70710700000000004 0 0"/>
        <body name="mbs3/mbs3_link3_link1" pos="0.083674999999999999 0 0" quat="0.70710700000000004 -0.70710700000000004 0 0">
          <inertial pos="0.032186399999999997 0 0" quat="0 0.70710700000000004 0 0.70710700000000004" mass="0.099320000000000006" diaginertia="6.8264700000000004e-05 5.7461299999999998e-05 2.71227e-05"/>
          <joint name="mbs3/mbs3_link3_joint1" class="mbs3/" pos="0 0 0" axis="0 1 0" range="-1.0471999999999999 1.0471999999999999" armature="0.002"/>
          <geom name="mbs3/mbs3_link3_link1_geom0" class="mbs3/" type="box" size="0.029149999999999999 0.025600000000000001 0.01" material="mbs3/geom_mbs3_link3_link1_geom0_material" pos="0.017999999999999999 0 0"/>
          <geom name="mbs3/mbs3_link3_link1_geom1" class="mbs3/" type="box" size="0.001 0.026499999999999999 0.026499999999999999" material="mbs3/geom_mbs3_link3_link1_geom1_material" pos="0.048149999999999998 0 0"/>
          <geom name="mbs3/mbs3_link3_link1_geom2" class="mbs3/" type="box" size="0.0089999999999999993 0.026499999999999999 0.0082945499999999995" material="mbs3/geom_mbs3_link3_link1_geom2_material" pos="0.05815 0 0" quat="0.70710700000000004 -0.70710700000000004 0 0"/>
          <body name="mbs3/mbs3_link3_link1_link1" pos="0.083674999999999999 0 0" quat="0.70710700000000004 -0.70710700000000004 0 0">
            <inertial pos="0.032186399999999997 0 0" quat="0 0.70710700000000004 0 0.70710700000000004" mass="0.099320000000000006" diaginertia="6.8264700000000004e-05 5.7461299999999998e-05 2.71227e-05"/>
            <joint name="mbs3/mbs3_link3_link1_joint1" class="mbs3/" pos="0 0 0" axis="0 1 0" range="-1.0471999999999999 1.0471999999999999" armature="0.002"/>
            <geom name="mbs3/mbs3_link3_link1_link1_geom0" class="mbs3/" type="box" size="0.029149999999999999 0.025600000000000001 0.01" material="mbs3/geom_mbs3_link3_link1_link1_geom0_material" pos="0.017999999999999999 0 0"/>
            <geom name="mbs3/mbs3_link3_link1_link1_geom1" class="mbs3/" type="box" size="0.001 0.026499999999999999 0.026499999999999999" material="mbs3/geom_mbs3_link3_link1_link1_geom1_material" pos="0.048149999999999998 0 0"/>
            <geom name="mbs3/mbs3_link3_link1_link1_geom2" class="mbs3/" type="box" size="0.0089999999999999993 0.026499999999999999 0.0082945499999999995" material="mbs3/geom_mbs3_link3_link1_link1_geom2_material" pos="0.05815 0 0" quat="0.70710700000000004 -0.70710700000000004 0 0"/>
            <body name="mbs3/mbs3_link3_link1_link1_link1" pos="0.083674999999999999 0 0" quat="0.70710700000000004 -0.70710700000000004 0 0">
              <inertial pos="0.032186399999999997 0 0" quat="0 0.70710700000000004 0 0.70710700000000004" mass="0.099320000000000006" diaginertia="6.8264700000000004e-05 5.7461299999999998e-05 2.71227e-05"/>
              <joint name="mbs3/mbs3_link3_link1_link1_joint1" class="mbs3/" pos="0 0 0" axis="0 1 0" range="-1.0471999999999999 1.0471999999999999" armature="0.002"/>
              <geom name="mbs3/mbs3_link3_link1_link1_link1_geom0" class="mbs3/" type="box" size="0.029149999999999999 0.025600000000000001 0.01" material="mbs3/geom_mbs3_link3_link1_link1_link1_geom0_material" pos="0.017999999999999999 0 0"/>
              <geom name="mbs3/mbs3_link3_link1_link1_link1_geom1" class="mbs3/" type="box" size="0.001 0.026499999999999999 0.026499999999999999" material="mbs3/geom_mbs3_link3_link1_link1_link1_geom1_material" pos="0.048149999999999998 0 0"/>
              <geom name="mbs3/mbs3_link3_link1_link1_link1_geom2" class="mbs3/" type="box" size="0.0089999999999999993 0.026499999999999999 0.0082945499999999995" material="mbs3/geom_mbs3_link3_link1_link1_link1_geom2_material" pos="0.05815 0 0" quat="0.70710700000000004 -0.70710700000000004 0 0"/>
              <body name="mbs3/mbs3_link3_link1_link1_link1_link1" pos="0.083674999999999999 0 0" quat="0.70710700000000004 -0.70710700000000004 0 0">
                <inertial pos="0.027081299999999999 0 0" quat="0 0.70710700000000004 0 0.70710700000000004" mass="0.083000000000000004" diaginertia="5.0839199999999999e-05 4.0102199999999997e-05 2.6307799999999999e-05"/>
                <joint name="mbs3/mbs3_link3_link1_link1_link1_joint1" class="mbs3/" pos="0 0 0" axis="0 1 0" range="-1.0471999999999999 1.0471999999999999" armature="0.002"/>
                <geom name="mbs3/mbs3_link3_link1_link1_link1_link1_geom0" class="mbs3/" type="box" size="0.029149999999999999 0.025600000000000001 0.01" material="mbs3/geom_mbs3_link3_link1_link1_link1_link1_geom0_material" pos="0.017999999999999999 0 0"/>
                <geom name="mbs3/mbs3_link3_link1_link1_link1_link1_geom1" class="mbs3/" type="box" size="0.001 0.026499999999999999 0.026499999999999999" material="mbs3/geom_mbs3_link3_link1_link1_link1_link1_geom1_material" pos="0.048149999999999998 0 0"/>
              </body>
            </body>
          </body>
        </body>
      </body>
    </body>
    <body pos="3 0 0" quat="0 0 0 1" name="mbs4/">
      <freejoint name="mbs4/"/>
      <geom name="mbs4/mbs4_geom0" class="mbs4/" type="box" size="0.074999999999999997 0.074999999999999997 0.074999999999999997" material="mbs4/geom_mbs4_geom0_material"/>
      <geom name="mbs4/mbs4_geom1" class="mbs4/" type="box" size="0.0089999999999999993 0.026499999999999999 0.0082945499999999995" material="mbs4/geom_mbs4_geom1_material" pos="0.084000000000000005 -0.029000000000000001 0.032000000000000001" quat="0.70710700000000004 -0.70710700000000004 0 0"/>
      <geom name="mbs4/mbs4_geom2" class="mbs4/" type="box" size="0.0089999999999999993 0.026499999999999999 0.0082945499999999995" material="mbs4/geom_mbs4_geom2_material" pos="-0.084000000000000005 0.029000000000000001 0.032000000000000001" quat="0 0 0.70710700000000004 -0.70710700000000004"/>
      <geom name="mbs4/mbs4_geom3" class="mbs4/" type="box" size="0.0089999999999999993 0.026499999999999999 0.0082945499999999995" material="mbs4/geom_mbs4_geom3_material" pos="0.029000000000000001 0.084000000000000005 0.032000000000000001" quat="0.5 -0.5 -0.5 0.5"/>
      <geom name="mbs4/mbs4_geom4" class="mbs4/" type="box" size="0.0089999999999999993 0.026499999999999999 0.0082945499999999995" material="mbs4/geom_mbs4_geom4_material" pos="-0.029000000000000001 -0.084000000000000005 0.032000000000000001" quat="0.5 -0.5 0.5 -0.5"/>
      <body name="mbs4/mbs4_link0" pos="0.109525 -0.029000000000000001 0.032000000000000001" quat="0.70710700000000004 -0.70710700000000004 0 0">
        <inertial pos="0.032186399999999997 0 0" quat="0 0.70710700000000004 0 0.70710700000000004" mass="0.099320000000000006" diaginertia="6.8264700000000004e-05 5.7461299999999998e-05 2.71227e-05"/>
        <joint name="mbs4/mbs4_joint0" class="mbs4/" pos="0 0 0" axis="0 1 0" range="-1.0471999999999999 1.0471999999999999" armature="0.002"/>
        <geom name="mbs4/mbs4_link0_geom0" class="mbs4/" type="box" size="0.029149999999999999 0.025600000000000001 0.01" material="mbs4/geom_mbs4_link0_geom0_material" pos="0.017999999999999999 0 0"/>
        <geom name="mbs4/mbs4_link0_geom1" class="mbs4/" type="box" size="0.001 0.026499999999999999 0.026499999999999999" material="mbs4/geom_mbs4_link0_geom1_material" pos="0.048149999999999998 0 0"/>
        <geom name="mbs4/mbs4_link0_geom2" class="mbs4/" type="box" size="0.0089999999999999993 0.026499999999999999 0.0082945499999999995" material="mbs4/geom_mbs4_link0_geom2_material" pos="0.05815 0 0" quat="0.70710700000000004 -0.70710700000000004 0 0"/>
        <body name="mbs4/mbs4_link0_link1" pos="0.083674999999999999 0 0" quat="0.70710700000000004 -0.70710700000000004 0 0">
          <inertial pos="0.032186399999999997 0 0" quat="0 0.70710700000000004 0 0.70710700000000004" mass="0.099320000000000006" diaginertia="6.8264700000000004e-05 5.7461299999999998e-05 2.71227e-05"/>
          <joint name="mbs4/mbs4_link0_joint1" class="mbs4/" pos="0 0 0" axis="0 1 0" range="-1.0471999999999999 1.0471999999999999" armature="0.002"/>
          <geom name="mbs4/mbs4_link0_link1_geom0" class="mbs4/" type="box" size="0.029149999999999999 0.025600000000000001 0.01" material="mbs4/geom_mbs4_link0_link1_geom0_material" pos="0.017999999999999999 0 0"/>
          <geom name="mbs4/mbs4_link0_link1_geom1" class="mbs4/" type="box" size="0.001 0.026499999999999999 0.026499999999999999" material="mbs4/geom_mbs4_link0_link1_geom1_material" pos="0.048149999999999998 0 0"/>
          <geom name="mbs4/mbs4_link0_link1_geom2" class="mbs4/" type="box" size="0.0089999999999999993 0.026499999999999999 0.0082945499999999995" material="mbs4/geom_mbs4_link0_link1_geom2_material" pos="0.05815 0 0" quat="0.70710700000000004 -0.70710700000000004 0 0"/>
          <body name="mbs4/mbs4_link0_link1_link1" pos="0.083674999999999999 0 0" quat="0.70710700000000004 -0.70710700000000004 0 0">
            <inertial pos="0.032186399999999997 0 0" quat="0 0.70710700000000004 0 0.70710700000000004" mass="0.099320000000000006" diaginertia="6.8264700000000004e-05 5.7461299999999998e-05 2.71227e-05"/>
            <joint name="mbs4/mbs4_link0_link1_joint1" class="mbs4/" pos="0 0 0" axis="0 1 0" range="-1.0471999999999999 1.0471999999999999" armature="0.002"/>
            <geom name="mbs4/mbs4_link0_link1_link1_geom0" class="mbs4/" type="box" size="0.029149999999999999 0.025600000000000001 0.01" material="mbs4/geom_mbs4_link0_link1_link1_geom0_material" pos="0.017999999999999999 0 0"/>
            <geom name="mbs4/mbs4_link0_link1_link1_geom1" class="mbs4/" type="box" size="0.001 0.026499999999999999 0.026499999999999999" material="mbs4/geom_mbs4_link0_link1_link1_geom1_material" pos="0.048149999999999998 0 0"/>
            <geom name="mbs4/mbs4_link0_link1_link1_geom2" class="mbs4/" type="box" size="0.0089999999999999993 0.026499999999999999 0.0082945499999999995" material="mbs4/geom_mbs4_link0_link1_link1_geom2_material" pos="0.05815 0 0" quat="0.70710700000000004 -0.70710700000000004 0 0"/>
            <body name="mbs4/mbs4_link0_link1_link1_link1" pos="0.083674999999999999 0 0" quat="0.70710700000000004 -0.70710700000000004 0 0">
              <inertial pos="0.032186399999999997 0 0" quat="0 0.70710700000000004 0 0.70710700000000004" mass="0.099320000000000006" diaginertia="6.8264700000000004e-05 5.7461299999999998e-05 2.71227e-05"/>
              <joint name="mbs4/mbs4_link0_link1_link1_joint1" class="mbs4/" pos="0 0 0" axis="0 1 0" range="-1.0471999999999999 1.0471999999999999" armature="0.002"/>
              <geom name="mbs4/mbs4_link0_link1_link1_link1_geom0" class="mbs4/" type="box" size="0.029149999999999999 0.025600000000000001 0.01" material="mbs4/geom_mbs4_link0_link1_link1_link1_geom0_material" pos="0.017999999999999999 0 0"/>
              <geom name="mbs4/mbs4_link0_link1_link1_link1_geom1" class="mbs4/" type="box" size="0.001 0.026499999999999999 0.026499999999999999" material="mbs4/geom_mbs4_link0_link1_link1_link1_geom1_material" pos="0.048149999999999998 0 0"/>
              <geom name="mbs4/mbs4_link0_link1_link1_link1_geom2" class="mbs4/" type="box" size="0.0089999999999999993 0.026499999999999999 0.0082945499999999995" material="mbs4/geom_mbs4_link0_link1_link1_link1_geom2_material" pos="0.05815 0 0" quat="0.70710700000000004 -0.70710700000000004 0 0"/>
              <body name="mbs4/mbs4_link0_link1_link1_link1_link1" pos="0.083674999999999999 0 0" quat="0.70710700000000004 -0.70710700000000004 0 0">
                <inertial pos="0.027081299999999999 0 0" quat="0 0.70710700000000004 0 0.70710700000000004" mass="0.083000000000000004" diaginertia="5.0839199999999999e-05 4.0102199999999997e-05 2.6307799999999999e-05"/>
                <joint name="mbs4/mbs4_link0_link1_link1_link1_joint1" class="mbs4/" pos="0 0 0" axis="0 1 0" range="-1.0471999999999999 1.0471999999999999" armature="0.002"/>
                <geom name="mbs4/mbs4_link0_link1_link1_link1_link1_geom0" class="mbs4/" type="box" size="0.029149999999999999 0.025600000000000001 0.01" material="mbs4/geom_mbs4_link0_link1_link1_link1_link1_geom0_material" pos="0.017999999999999999 0 0"/>
                <geom name="mbs4/mbs4_link0_link1_link1_link1_link1_geom1" class="mbs4/" type="box" size="0.001 0.026499999999999999 0.026499999999999999" material="mbs4/geom_mbs4_link0_link1_link1_link1_link1_geom1_material" pos="0.048149999999999998 0 0"/>
              </body>
            </body>
          </body>
        </body>
      </body>
      <body name="mbs4/mbs4_link1" pos="-0.109525 0.029000000000000001 0.032000000000000001" quat="0 0 0.70710700000000004 -0.70710700000000004">
        <inertial pos="0.032186399999999997 0 0" quat="0 0.70710700000000004 0 0.70710700000000004" mass="0.099320000000000006" diaginertia="6.8264700000000004e-05 5.7461299999999998e-05 2.71227e-05"/>
        <joint name="mbs4/mbs4_joint1" class="mbs4/" pos="0 0 0" axis="0 1 0" range="-1.0471999999999999 1.0471999999999999" armature="0.002"/>
        <geom name="mbs4/mbs4_link1_geom0" class="mbs4/" type="box" size="0.029149999999999999 0.025600000000000001 0.01" material="mbs4/geom_mbs4_link1_geom0_material" pos="0.017999999999999999 0 0"/>
        <geom name="mbs4/mbs4_link1_geom1" class="mbs4/" type="box" size="0.001 0.026499999999999999 0.026499999999999999" material="mbs4/geom_mbs4_link1_geom1_material" pos="0.048149999999999998 0 0"/>
        <geom name="mbs4/mbs4_link1_geom2" class="mbs4/" type="box" size="0.0089999999999999993 0.026499999999999999 0.0082945499999999995" material="mbs4/geom_mbs4_link1_geom2_material" pos="0.05815 0 0" quat="0.70710700000000004 -0.70710700000000004 0 0"/>
        <body name="mbs4/mbs4_link1_link1" pos="0.083674999999999999 0 0" quat="0.70710700000000004 -0.70710700000000004 0 0">
          <inertial pos="0.032186399999999997 0 0" quat="0 0.70710700000000004 0 0.70710700000000004" mass="0.099320000000000006" diaginertia="6.8264700000000004e-05 5.7461299999999998e-05 2.71227e-05"/>
          <joint name="mbs4/mbs4_link1_joint1" class="mbs4/" pos="0 0 0" axis="0 1 0" range="-1.0471999999999999 1.0471999999999999" armature="0.002"/>
          <geom name="mbs4/mbs4_link1_link1_geom0" class="mbs4/" type="box" size="0.029149999999999999 0.025600000000000001 0.01" material="mbs4/geom_mbs4_link1_link1_geom0_material" pos="0.017999999999999999 0 0"/>
          <geom name="mbs4/mbs4_link1_link1_geom1" class="mbs4/" type="box" size="0.001 0.026499999999999999 0.026499999999999999" material="mbs4/geom_mbs4_link1_link1_geom1_material" pos="0.048149999999999998 0 0"/>
          <geom name="mbs4/mbs4_link1_link1_geom2" class="mbs4/" type="box" size="0.0089999999999999993 0.026499999999999999 0.0082945499999999995" material="mbs4/geom_mbs4_link1_link1_geom2_material" pos="0.05815 0 0" quat="0.70710700000000004 -0.70710700000000004 0 0"/>
          <body name="mbs4/mbs4_link1_link1_link1" pos="0.083674999999999999 0 0" quat="0.70710700000000004 -0.70710700000000004 0 0">
            <inertial pos="0.032186399999999997 0 0" quat="0 0.70710700000000004 0 0.70710700000000004" mass="0.099320000000000006" diaginertia="6.8264700000000004e-05 5.7461299999999998e-05 2.71227e-05"/>
            <joint name="mbs4/mbs4_link1_link1_joint1" class="mbs4/" pos="0 0 0" axis="0 1 0" range="-1.0471999999999999 1.0471999999999999" armature="0.002"/>
            <geom name="mbs4/mbs4_link1_link1_link1_geom0" class="mbs4/" type="box" size="0.029149999999999999 0.025600000000000001 0.01" material="mbs4/geom_mbs4_link1_link1_link1_geom0_material" pos="0.017999999999999999 0 0"/>
            <geom name="mbs4/mbs4_link1_link1_link1_geom1" class="mbs4/" type="box" size="0.001 0.026499999999999999 0.026499999999999999" material="mbs4/geom_mbs4_link1_link1_link1_geom1_material" pos="0.048149999999999998 0 0"/>
            <geom name="mbs4/mbs4_link1_link1_link1_geom2" class="mbs4/" type="box" size="0.0089999999999999993 0.026499999999999999 0.0082945499999999995" material="mbs4/geom_mbs4_link1_link1_link1_geom2_material" pos="0.05815 0 0" quat="0.70710700000000004 -0.70710700000000004 0 0"/>
            <body name="mbs4/mbs4_link1_link1_link1_link1" pos="0.083674999999999999 0 0" quat="0.70710700000000004 -0.70710700000000004 0 0">
              <inertial pos="0.032186399999999997 0 0" quat="0 0.70710700000000004 0 0.70710700000000004" mass="0.099320000000000006" diaginertia="6.8264700000000004e-05 5.7461299999999998e-05 2.71227e-05"/>
              <joint name="mbs4/mbs4_link1_link1_link1_joint1" class="mbs4/" pos="0 0 0" axis="0 1 0" range="-1.0471999999999999 1.0471999999999999" armature="0.002"/>
              <geom name="mbs4/mbs4_link1_link1_link1_link1_geom0" class="mbs4/" type="box" size="0.029149999999999999 0.025600000000000001 0.01" material="mbs4/geom_mbs4_link1_link1_link1_link1_geom0_material" pos="0.017999999999999999 0 0"/>
              <geom name="mbs4/mbs4_link1_link1_link1_link1_geom1" class="mbs4/" type="box" size="0.001 0.026499999999999999 0.026499999999999999" material="mbs4/geom_mbs4_link1_link1_link1_link1_geom1_material" pos="0.048149999999999998 0 0"/>
              <geom name="mbs4/mbs4_link1_link1_link1_link1_geom2" class="mbs4/" type="box" size="0.0089999999999999993 0.026499999999999999 0.0082945499999999995" material="mbs4/geom_mbs4_link1_link1_link1_link1_geom2_material" pos="0.05815 0 0" quat="0.70710700000000004 -0.70710700000000004 0 0"/>
              <body name="mbs4/mbs4_link1_link1_link1_link1_link1" pos="0.083674999999999999 0 0" quat="0.70710700000000004 -0.70710700000000004 0 0">
                <inertial pos="0.027081299999999999 0 0" quat="0 0.70710700000000004 0 0.70710700000000004" mass="0.083000000000000004" diaginertia="5.0839199999999999e-05 4.0102199999999997e-05 2.6307799999999999e-05"/>
                <joint name="mbs4/mbs4_link1_link1_link1_link1_joint1" class="mbs4/" pos="0 0 0" axis="0 1 0" range="-1.0471999999999999 1.0471999999999999" armature="0.002"/>
                <geom name="mbs4/mbs4_link1_link1_link1_link1_link1_geom0" class="mbs4/" type="box" size="0.029149999999999999 0.025600000000000001 0.01" material="mbs4/geom_mbs4_link1_link1_link1_link1_link1_geom0_material" pos="0.017999999999999999 0 0"/>
                <geom name="mbs4/mbs4_link1_link1_link1_link1_link1_geom1" class="mbs4/" type="box" size="0.001 0.026499999999999999 0.026499999999999999" material="mbs4/geom_mbs4_link1_link1_link1_link1_link1_geom1_material" pos="0.048149999999999998 0 0"/>
              </body>
            </body>
          </body>
        </body>
      </body>
      <body name="mbs4/mbs4_link2" pos="0.029000000000000001 0.109525 0.032000000000000001" quat="0.5 -0.5 -0.5 0.5">
        <inertial pos="0.032186399999999997 0 0" quat="0 0.70710700000000004 0 0.70710700000000004" mass="0.099320000000000006" diaginertia="6.8264700000000004e-05 5.7461299999999998e-05 2.71227e-05"/>
        <joint name="mbs4/mbs4_joint2" class="mbs4/" pos="0 0 0" axis="0 1 0" range="-1.0471999999999999 1.0471999999999999" armature="0.002"/>
        <geom name="mbs4/mbs4_link2_geom0" class="mbs4/" type="box" size="0.029149999999999999 0.025600000000000001 0.01" material="mbs4/geom_mbs4_link2_geom0_material" pos="0.017999999999999999 0 0"/>
        <geom name="mbs4/mbs4_link2_geom1" class="mbs4/" type="box" size="0.001 0.026499999999999999 0.026499999999999999" material="mbs4/geom_mbs4_link2_geom1_material" pos="0.048149999999999998 0 0"/>
        <geom name="mbs4/mbs4_link2_geom2" class="mbs4/" type="box" size="0.0089999999999999993 0.026499999999999999 0.0082945499999999995" material="mbs4/geom_mbs4_link2_geom2_material" pos="0.05815 0 0" quat="0.70710700000000004 -0.70710700000000004 0 0"/>
        <body name="mbs4/mbs4_link2_link1" pos="0.083674999999999999 0 0" quat="0.70710700000000004 -0.70710700000000004 0 0">
          <inertial pos="0.032186399999999997 0 0" quat="0 0.70710700000000004 0 0.70710700000000004" mass="0.099320000000000006" diaginertia="6.8264700000000004e-05 5.7461299999999998e-05 2.71227e-05"/>
          <joint name="mbs4/mbs4_link2_joint1" class="mbs4/" pos="0 0 0" axis="0 1 0" range="-1.0471999999999999 1.0471999999999999" armature="0.002"/>
          <geom name="mbs4/mbs4_link2_link1_geom0" class="mbs4/" type="box" size="0.029149999999999999 0.025600000000000001 0.01" material="mbs4/geom_mbs4_link2_link1_geom0_material" pos="0.017999999999999999 0 0"/>
          <geom name="mbs4/mbs4_link2_link1_geom1" class="mbs4/" type="box" size="0.001 0.026499999999999999 0.026499999999999999" material="mbs4/geom_mbs4_link2_link1_geom1_material" pos="0.048149999999999998 0 0"/>
          <geom name="mbs4/mbs4_link2_link1_geom2" class="mbs4/" type="box" size="0.0089999999999999993 0.026499999999999999 0.0082945499999999995" material="mbs4/geom_mbs4_link2_link1_geom2_material" pos="0.05815 0 0" quat="0.70710700000000004 -0.70710700000000004 0 0"/>
          <body name="mbs4/mbs4_link2_link1_link1" pos="0.083674999999999999 0 0" quat="0.70710700000000004 -0.70710700000000004 0 0">
            <inertial pos="0.032186399999999997 0 0" quat="0 0.70710700000000004 0 0.70710700000000004" mass="0.099320000000000006" diaginertia="6.8264700000000004e-05 5.7461299999999998e-05 2.71227e-05"/>
            <joint name="mbs4/mbs4_link2_link1_joint1" class="mbs4/" pos="0 0 0" axis="0 1 0" range="-1.0471999999999999 1.0471999999999999" armature="0.002"/>
            <geom name="mbs4/mbs4_link2_link1_link1_geom0" class="mbs4/" type="box" size="0.029149999999999999 0.025600000000000001 0.01" material="mbs4/geom_mbs4_link2_link1_link1_geom0_material" pos="0.017999999999999999 0 0"/>
            <geom name="mbs4/mbs4_link2_link1_link1_geom1" class="mbs4/" type="box" size="0.001 0.026499999999999999 0.026499999999999999" material="mbs4/geom_mbs4_link2_link1_link1_geom1_material" pos="0.048149999999999998 0 0"/>
            <geom name="mbs4/mbs4_link2_link1_link1_geom2" class="mbs4/" type="box" size="0.0089999999999999993 0.026499999999999999 0.0082945499999999995" material="mbs4/geom_mbs4_link2_link1_link1_geom2_material" pos="0.05815 0 0" quat="0.70710700000000004 -0.70710700000000004 0 0"/>
            <body name="mbs4/mbs4_link2_link1_link1_link1" pos="0.083674999999999999 0 0" quat="0.70710700000000004 -0.70710700000000004 0 0">
              <inertial pos="0.027081299999999999 0 0" quat="0 0.70710700000000004 0 0.70710700000000004" mass="0.083000000000000004" diaginertia="5.0839199999999999e-05 4.0102199999999997e-05 2.6307799999999999e-05"/>
              <joint name="mbs4/mbs4_link2_link1_link1_joint1" class="mbs4/" pos="0 0 0" axis="0 1 0" range="-1.0471999999999999 1.0471999999999999" armature="0.002"/>
              <geom name="mbs4/mbs4_link2_link1_link1_link1_geom0" class="mbs4/" type="box" size="0.029149999999999999 0.025600000000000001 0.01" material="mbs4/geom_mbs4_link2_link1_link1_link1_geom0_material" pos="0.017999999999999999 0 0"/>
              <geom name="mbs4/mbs4_link2_link1_link1_link1_geom1" class="mbs4/" type="box" size="0.001 0.026499999999999999 0.026499999999999999" material="mbs4/geom_mbs4_link2_link1_link1_link1_geom1_material" pos="0.048149999999999998 0 0"/>
            </body>
          </body>
        </body>
      </body>
      <body name="mbs4/mbs4_link3" pos="-0.029000000000000001 -0.109525 0.032000000000000001" quat="0.5 -0.5 0.5 -0.5">
        <inertial pos="0.032186399999999997 0 0" quat="0 0.70710700000000004 0 0.70710700000000004" mass="0.099320000000000006" diaginertia="6.8264700000000004e-05 5.7461299999999998e-05 2.71227e-05"/>
        <joint name="mbs4/mbs4_joint3" class="mbs4/" pos="0 0 0" axis="0 1 0" range="-1.0471999999999999 1.0471999999999999" armature="0.002"/>
        <geom name="mbs4/mbs4_link3_geom0" class="mbs4/" type="box" size="0.029149999999999999 0.025600000000000001 0.01" material="mbs4/geom_mbs4_link3_geom0_material" pos="0.017999999999999999 0 0"/>
        <geom name="mbs4/mbs4_link3_geom1" class="mbs4/" type="box" size="0.001 0.026499999999999999 0.026499999999999999" material="mbs4/geom_mbs4_link3_geom1_material" pos="0.048149999999999998 0 0"/>
        <geom name="mbs4/mbs4_link3_geom2" class="mbs4/" type="box" size="0.0089999999999999993 0.026499999999999999 0.0082945499999999995" material="mbs4/geom_mbs4_link3_geom2_material" pos="0.05815 0 0" quat="0.70710700000000004 -0.70710700000000004 0 0"/>
        <body name="mbs4/mbs4_link3_link1" pos="0.083674999999999999 0 0" quat="0.70710700000000004 -0.70710700000000004 0 0">
          <inertial pos="0.032186399999999997 0 0" quat="0 0.70710700000000004 0 0.70710700000000004" mass="0.099320000000000006" diaginertia="6.8264700000000004e-05 5.7461299999999998e-05 2.71227e-05"/>
          <joint name="mbs4/mbs4_link3_joint1" class="mbs4/" pos="0 0 0" axis="0 1 0" range="-1.0471999999999999 1.0471999999999999" armature="0.002"/>
          <geom name="mbs4/mbs4_link3_link1_geom0" class="mbs4/" type="box" size="0.029149999999999999 0.025600000000000001 0.01" material="mbs4/geom_mbs4_link3_link1_geom0_material" pos="0.017999999999999999 0 0"/>
          <geom name="mbs4/mbs4_link3_link1_geom1" class="mbs4/" type="box" size="0.001 0.026499999999999999 0.026499999999999999" material="mbs4/geom_mbs4_link3_link1_geom1_material" pos="0.048149999999999998 0 0"/>
          <geom name="mbs4/mbs4_link3_link1_geom2" class="mbs4/" type="box" size="0.0089999999999999993 0.026499999999999999 0.0082945499999999995" material="mbs4/geom_mbs4_link3_link1_geom2_material" pos="0.05815 0 0" quat="0.70710700000000004 -0.70710700000000004 0 0"/>
          <body name="mbs4/mbs4_link3_link1_link1" pos="0.083674999999999999 0 0" quat="0.70710700000000004 -0.70710700000000004 0 0">
            <inertial pos="0.032186399999999997 0 0" quat="0 0.70710700000000004 0 0.70710700000000004" mass="0.099320000000000006" diaginertia="6.8264700000000004e-05 5.7461299999999998e-05 2.71227e-05"/>
            <joint name="mbs4/mbs4_link3_link1_joint1" class="mbs4/" pos="0 0 0" axis="0 1 0" range="-1.0471999999999999 1.0471999999999999" armature="0.002"/>
            <geom name="mbs4/mbs4_link3_link1_link1_geom0" class="mbs4/" type="box" size="0.029149999999999999 0.025600000000000001 0.01" material="mbs4/geom_mbs4_link3_link1_link1_geom0_material" pos="0.017999999999999999 0 0"/>
            <geom name="mbs4/mbs4_link3_link1_link1_geom1" class="mbs4/" type="box" size="0.001 0.026499999999999999 0.026499999999999999" material="mbs4/geom_mbs4_link3_link1_link1_geom1_material" pos="0.048149999999999998 0 0"/>
            <geom name="mbs4/mbs4_link3_link1_link1_geom2" class="mbs4/" type="box" size="0.0089999999999999993 0.026499999999999999 0.0082945499999999995" material="mbs4/geom_mbs4_link3_link1_link1_geom2_material" pos="0.05815 0 0" quat="0.70710700000000004 -0.70710700000000004 0 0"/>
            <body name="mbs4/mbs4_link3_link1_link1_link1" pos="0.083674999999999999 0 0" quat="0.70710700000000004 -0.70710700000000004 0 0">
              <inertial pos="0.032186399999999997 0 0" quat="0 0.70710700000000004 0 0.70710700000000004" mass="0.099320000000000006" diaginertia="6.8264700000000004e-05 5.7461299999999998e-05 2.71227e-05"/>
              <joint name="mbs4/mbs4_link3_link1_link1_joint1" class="mbs4/" pos="0 0 0" axis="0 1 0" range="-1.0471999999999999 1.0471999999999999" armature="0.002"/>
              <geom name="mbs4/mbs4_link3_link1_link1_link1_geom0" class="mbs4/" type="box" size="0.029149999999999999 0.025600000000000001 0.01" material="mbs4/geom_mbs4_link3_link1_link1_link1_geom0_material" pos="0.017999999999999999 0 0"/>
              <geom name="mbs4/mbs4_link3_link1_link1_link1_geom1" class="mbs4/" type="box" size="0.001 0.026499999999999999 0.026499999999999999" material="mbs4/geom_mbs4_link3_link1_link1_link1_geom1_material" pos="0.048149999999999998 0 0"/>
              <geom name="mbs4/mbs4_link3_link1_link1_link1_geom2" class="mbs4/" type="box" size="0.0089999999999999993 0.026499999999999999 0.0082945499999999995" material="mbs4/geom_mbs4_link3_link1_link1_link1_geom2_material" pos="0.05815 0 0" quat="0.70710700000000004 -0.70710700000000004 0 0"/>
              <body name="mbs4/mbs4_link3_link1_link1_link1_link1" pos="0.083674999999999999 0 0" quat="0.70710700000000004 -0.70710700000000004 0 0">
                <inertial pos="0.027081299999999999 0 0" quat="0 0.70710700000000004 0 0.70710700000000004" mass="0.083000000000000004" diaginertia="5.0839199999999999e-05 4.0102199999999997e-05 2.6307799999999999e-05"/>
                <joint name="mbs4/mbs4_link3_link1_link1_link1_joint1" class="mbs4/" pos="0 0 0" axis="0 1 0" range="-1.0471999999999999 1.0471999999999999" armature="0.002"/>
                <geom name="mbs4/mbs4_link3_link1_link1_link1_link1_geom0" class="mbs4/" type="box" size="0.029149999999999999 0.025600000000000001 0.01" material="mbs4/geom_mbs4_link3_link1_link1_link1_link1_geom0_material" pos="0.017999999999999999 0 0"/>
                <geom name="mbs4/mbs4_link3_link1_link1_link1_link1_geom1" class="mbs4/" type="box" size="0.001 0.026499999999999999 0.026499999999999999" material="mbs4/geom_mbs4_link3_link1_link1_link1_link1_geom1_material" pos="0.048149999999999998 0 0"/>
              </body>
            </body>
          </body>
        </body>
      </body>
    </body>
    <body pos="4 0 0" quat="0 0 0 1" name="mbs5/">
      <freejoint name="mbs5/"/>
      <geom name="mbs5/mbs5_geom0" class="mbs5/" type="box" size="0.074999999999999997 0.074999999999999997 0.074999999999999997" material="mbs5/geom_mbs5_geom0_material"/>
    </body>
    <body pos="5 0 0" quat="0 0 0 1" name="mbs6/">
      <freejoint name="mbs6/"/>
      <geom name="mbs6/mbs6_geom0" class="mbs6/" type="box" size="0.074999999999999997 0.074999999999999997 0.074999999999999997" material="mbs6/geom_mbs6_geom0_material"/>
      <geom name="mbs6/mbs6_geom1" class="mbs6/" type="box" size="0.031443100000000002 0.031443100000000002 0.03015" material="mbs6/geom_mbs6_geom1_material" pos="0.106443 -0.029000000000000001 0.032000000000000001" quat="0.70710700000000004 0.70710700000000004 0 0"/>
      <geom name="mbs6/mbs6_geom2" class="mbs6/" type="box" size="0.031443100000000002 0.031443100000000002 0.03015" material="mbs6/geom_mbs6_geom2_material" pos="-0.106443 0.029000000000000001 0.032000000000000001" quat="0 0 0.70710700000000004 0.70710700000000004"/>
      <geom name="mbs6/mbs6_geom3" class="mbs6/" type="box" size="0.031443100000000002 0.031443100000000002 0.03015" material="mbs6/geom_mbs6_geom3_material" pos="0.029000000000000001 0.106443 0.032000000000000001" quat="0.5 0.5 0.5 0.5"/>
      <geom name="mbs6/mbs6_geom4" class="mbs6/" type="box" size="0.031443100000000002 0.031443100000000002 0.03015" material="mbs6/geom_mbs6_geom4_material" pos="-0.029000000000000001 -0.106443 0.032000000000000001" quat="0.5 0.5 -0.5 -0.5"/>
      <geom name="mbs6/mbs6_geom5" class="mbs6/" type="box" size="0.031443100000000002 0.031443100000000002 0.03015" material="mbs6/geom_mbs6_geom5_material" pos="0.16932900000000001 -0.029000000000000001 0.032000000000000001" quat="0 1 0 0"/>
      <geom name="mbs6/mbs6_geom6" class="mbs6/" type="box" size="0.031443100000000002 0.031443100000000002 0.03015" material="mbs6/geom_mbs6_geom6_material" pos="0.106443 -0.029000000000000001 0.094886300000000007" quat="0 0.70710700000000004 0 0.70710700000000004"/>
      <geom name="mbs6/mbs6_geom7" class="mbs6/" type="box" size="0.031443100000000002 0.031443100000000002 0.03015" material="mbs6/geom_mbs6_geom7_material" pos="0.106443 -0.029000000000000001 -0.030886299999999998" quat="0 0.70710700000000004 0 -0.70710700000000004"/>
      <geom name="mbs6/mbs6_geom8" class="mbs6/" type="box" size="0.031443100000000002 0.031443100000000002 0.03015" material="mbs6/geom_mbs6_geom8_material" pos="-0.16932900000000001 0.029000000000000001 0.032000000000000001" quat="0 0 1 0"/>
      <geom name="mbs6/mbs6_geom9" class="mbs6/" type="box" size="0.031443100000000002 0.031443100000000002 0.03015" material="mbs6/geom_mbs6_geom9_material" pos="-0.106443 0.029000000000000001 0.094886200000000004" quat="0.70710700000000004 0 -0.70710700000000004 0"/>
      <geom name="mbs6/mbs6_geom10" class="mbs6/" type="box" size="0.031443100000000002 0.031443100000000002 0.03015" material="mbs6/geom_mbs6_geom10_material" pos="-0.106443 0.029000000000000001 -0.030886199999999999" quat="0.70710700000000004 0 0.70710700000000004 0"/>
      <geom name="mbs6/mbs6_geom11" class="mbs6/" type="box" size="0.031443100000000002 0.031443100000000002 0.03015" material="mbs6/geom_mbs6_geom11_material" pos="0.029000000000000001 0.16932900000000001 0.032000000000000001" quat="0 0.70710700000000004 0.70710700000000004 0"/>
      <geom name="mbs6/mbs6_geom12" class="mbs6/" type="box" size="0.031443100000000002 0.031443100000000002 0.03015" material="mbs6/geom_mbs6_geom12_material" pos="0.029000000000000001 0.106443 0.094886300000000007" quat="0.5 -0.5 -0.5 -0.5"/>
      <geom name="mbs6/mbs6_geom13" class="mbs6/" type="box" size="0.031443100000000002 0.031443100000000002 0.03015" material="mbs6/geom_mbs6_geom13_material" pos="0.029000000000000001 0.106443 -0.030886299999999998" quat="0.5 0.5 0.5 -0.5"/>
      <geom name="mbs6/mbs6_geom14" class="mbs6/" type="box" size="0.031443100000000002 0.031443100000000002 0.03015" material="mbs6/geom_mbs6_geom14_material" pos="-0.029000000000000001 -0.16932900000000001 0.032000000000000001" quat="0 0.70710700000000004 -0.70710700000000004 0"/>
      <geom name="mbs6/mbs6_geom15" class="mbs6/" type="box" size="0.031443100000000002 0.031443100000000002 0.03015" material="mbs6/geom_mbs6_geom15_material" pos="-0.029000000000000001 -0.106443 0.094886300000000007" quat="0.5 0.5 -0.5 0.5"/>
      <geom name="mbs6/mbs6_geom16" class="mbs6/" type="box" size="0.031443100000000002 0.031443100000000002 0.03015" material="mbs6/geom_mbs6_geom16_material" pos="-0.029000000000000001 -0.106443 -0.030886299999999998" quat="0.5 -0.5 0.5 0.5"/>
      <geom name="mbs6/mbs6_geom17" class="mbs6/" type="box" size="0.031443100000000002 0.031443100000000002 0.03015" material="mbs6/geom_mbs6_geom17_material" pos="0.23221600000000001 -0.029000000000000001 0.032000000000000001" quat="0.70710700000000004 -0.70710700000000004 0 0"/>
      <geom name="mbs6/mbs6_geom18" class="mbs6/" type="box" size="0.031443100000000002 0.031443100000000002 0.03015" material="mbs6/geom_mbs6_geom18_material" pos="0.16932900000000001 -0.091886300000000004 0.032000000000000001" quat="0.5 -0.5 0.5 -0.5"/>
      <geom name="mbs6/mbs6_geom19" class="mbs6/" type="box" size="0.031443100000000002 0.031443100000000002 0.03015" material="mbs6/geom_mbs6_geom19_material" pos="0.16932900000000001 0.033886300000000001 0.032000000000000001" quat="0.5 -0.5 -0.5 0.5"/>
    </body>
  </worldbody>
  <actuator>
    <position name="mbs2/actuator_position_mbs2_joint0" class="mbs2/" joint="mbs2/mbs2_joint0" kp="5"/>
    <velocity name="mbs2/actuator_velocity_mbs2_joint0" class="mbs2/" joint="mbs2/mbs2_joint0" kv="0.050000000000000003"/>
    <position name="mbs2/actuator_position_mbs2_link0_joint1" class="mbs2/" joint="mbs2/mbs2_link0_joint1" kp="5"/>
    <velocity name="mbs2/actuator_velocity_mbs2_link0_joint1" class="mbs2/" joint="mbs2/mbs2_link0_joint1" kv="0.050000000000000003"/>
    <position name="mbs2/actuator_position_mbs2_link0_link1_joint1" class="mbs2/" joint="mbs2/mbs2_link0_link1_joint1" kp="5"/>
    <velocity name="mbs2/actuator_velocity_mbs2_link0_link1_joint1" class="mbs2/" joint="mbs2/mbs2_link0_link1_joint1" kv="0.050000000000000003"/>
    <position name="mbs2/actuator_position_mbs2_link0_link1_link1_joint1" class="mbs2/" joint="mbs2/mbs2_link0_link1_link1_joint1" kp="5"/>
    <velocity name="mbs2/actuator_velocity_mbs2_link0_link1_link1_joint1" class="mbs2/" joint="mbs2/mbs2_link0_link1_link1_joint1" kv="0.050000000000000003"/>
    <position name="mbs2/actuator_position_mbs2_link0_link1_link1_link1_joint1" class="mbs2/" joint="mbs2/mbs2_link0_link1_link1_link1_joint1" kp="5"/>
    <velocity name="mbs2/actuator_velocity_mbs2_link0_link1_link1_link1_joint1" class="mbs2/" joint="mbs2/mbs2_link0_link1_link1_link1_joint1" kv="0.050000000000000003"/>
    <position name="mbs2/actuator_position_mbs2_joint1" class="mbs2/" joint="mbs2/mbs2_joint1" kp="5"/>
    <velocity name="mbs2/actuator_velocity_mbs2_joint1" class="mbs2/" joint="mbs2/mbs2_joint1" kv="0.050000000000000003"/>
    <position name="mbs2/actuator_position_mbs2_link1_joint1" class="mbs2/" joint="mbs2/mbs2_link1_joint1" kp="5"/>
    <velocity name="mbs2/actuator_velocity_mbs2_link1_joint1" class="mbs2/" joint="mbs2/mbs2_link1_joint1" kv="0.050000000000000003"/>
    <position name="mbs2/actuator_position_mbs2_link1_link1_joint1" class="mbs2/" joint="mbs2/mbs2_link1_link1_joint1" kp="5"/>
    <velocity name="mbs2/actuator_velocity_mbs2_link1_link1_joint1" class="mbs2/" joint="mbs2/mbs2_link1_link1_joint1" kv="0.050000000000000003"/>
    <position name="mbs2/actuator_position_mbs2_link1_link1_link1_joint1" class="mbs2/" joint="mbs2/mbs2_link1_link1_link1_joint1" kp="5"/>
    <velocity name="mbs2/actuator_velocity_mbs2_link1_link1_link1_joint1" class="mbs2/" joint="mbs2/mbs2_link1_link1_link1_joint1" kv="0.050000000000000003"/>
    <position name="mbs2/actuator_position_mbs2_link1_link1_link1_link1_joint1" class="mbs2/" joint="mbs2/mbs2_link1_link1_link1_link1_joint1" kp="5"/>
    <velocity name="mbs2/actuator_velocity_mbs2_link1_link1_link1_link1_joint1" class="mbs2/" joint="mbs2/mbs2_link1_link1_link1_link1_joint1" kv="0.050000000000000003"/>
    <position name="mbs2/actuator_position_mbs2_joint2" class="mbs2/" joint="mbs2/mbs2_joint2" kp="5"/>
    <velocity name="mbs2/actuator_velocity_mbs2_joint2" class="mbs2/" joint="mbs2/mbs2_joint2" kv="0.050000000000000003"/>
    <position name="mbs2/actuator_position_mbs2_link2_joint1" class="mbs2/" joint="mbs2/mbs2_link2_joint1" kp="5"/>
    <velocity name="mbs2/actuator_velocity_mbs2_link2_joint1" class="mbs2/" joint="mbs2/mbs2_link2_joint1" kv="0.050000000000000003"/>
    <position name="mbs2/actuator_position_mbs2_link2_link1_joint1" class="mbs2/" joint="mbs2/mbs2_link2_link1_joint1" kp="5"/>
    <velocity name="mbs2/actuator_velocity_mbs2_link2_link1_joint1" class="mbs2/" joint="mbs2/mbs2_link2_link1_joint1" kv="0.050000000000000003"/>
    <position name="mbs2/actuator_position_mbs2_link2_link1_link1_joint1" class="mbs2/" joint="mbs2/mbs2_link2_link1_link1_joint1" kp="5"/>
    <velocity name="mbs2/actuator_velocity_mbs2_link2_link1_link1_joint1" class="mbs2/" joint="mbs2/mbs2_link2_link1_link1_joint1" kv="0.050000000000000003"/>
    <position name="mbs2/actuator_position_mbs2_joint3" class="mbs2/" joint="mbs2/mbs2_joint3" kp="5"/>
    <velocity name="mbs2/actuator_velocity_mbs2_joint3" class="mbs2/" joint="mbs2/mbs2_joint3" kv="0.050000000000000003"/>
    <position name="mbs2/actuator_position_mbs2_link3_joint1" class="mbs2/" joint="mbs2/mbs2_link3_joint1" kp="5"/>
    <velocity name="mbs2/actuator_velocity_mbs2_link3_joint1" class="mbs2/" joint="mbs2/mbs2_link3_joint1" kv="0.050000000000000003"/>
    <position name="mbs2/actuator_position_mbs2_link3_link1_joint1" class="mbs2/" joint="mbs2/mbs2_link3_link1_joint1" kp="5"/>
    <velocity name="mbs2/actuator_velocity_mbs2_link3_link1_joint1" class="mbs2/" joint="mbs2/mbs2_link3_link1_joint1" kv="0.050000000000000003"/>
    <position name="mbs2/actuator_position_mbs2_link3_link1_link1_joint1" class="mbs2/" joint="mbs2/mbs2_link3_link1_link1_joint1" kp="5"/>
    <velocity name="mbs2/actuator_velocity_mbs2_link3_link1_link1_joint1" class="mbs2/" joint="mbs2/mbs2_link3_link1_link1_joint1" kv="0.050000000000000003"/>
    <position name="mbs2/actuator_position_mbs2_link3_link1_link1_link1_joint1" class="mbs2/" joint="mbs2/mbs2_link3_link1_link1_link1_joint1" kp="5"/>
    <velocity name="mbs2/actuator_velocity_mbs2_link3_link1_link1_link1_joint1" class="mbs2/" joint="mbs2/mbs2_link3_link1_link1_link1_joint1" kv="0.050000000000000003"/>
    <position name="mbs3/actuator_position_mbs3_joint0" class="mbs3/" joint="mbs3/mbs3_joint0" kp="5"/>
    <velocity name="mbs3/actuator_velocity_mbs3_joint0" class="mbs3/" joint="mbs3/mbs3_joint0" kv="0.050000000000000003"/>
    <position name="mbs3/actuator_position_mbs3_link0_joint1" class="mbs3/" joint="mbs3/mbs3_link0_joint1" kp="5"/>
    <velocity name="mbs3/actuator_velocity_mbs3_link0_joint1" class="mbs3/" joint="mbs3/mbs3_link0_joint1" kv="0.050000000000000003"/>
    <position name="mbs3/actuator_position_mbs3_link0_link1_joint1" class="mbs3/" joint="mbs3/mbs3_link0_link1_joint1" kp="5"/>
    <velocity name="mbs3/actuator_velocity_mbs3_link0_link1_joint1" class="mbs3/" joint="mbs3/mbs3_link0_link1_joint1" kv="0.050000000000000003"/>
    <position name="mbs3/actuator_position_mbs3_link0_link1_link1_joint1" class="mbs3/" joint="mbs3/mbs3_link0_link1_link1_joint1" kp="5"/>
    <velocity name="mbs3/actuator_velocity_mbs3_link0_link1_link1_joint1" class="mbs3/" joint="mbs3/mbs3_link0_link1_link1_joint1" kv="0.050000000000000003"/>
    <position name="mbs3/actuator_position_mbs3_link0_link1_link1_link1_joint1" class="mbs3/" joint="mbs3/mbs3_link0_link1_link1_link1_joint1" kp="5"/>
    <velocity name="mbs3/actuator_velocity_mbs3_link0_link1_link1_link1_joint1" class="mbs3/" joint="mbs3/mbs3_link0_link1_link1_link1_joint1" kv="0.050000000000000003"/>
    <position name="mbs3/actuator_position_mbs3_joint1" class="mbs3/" joint="mbs3/mbs3_joint1" kp="5"/>
    <velocity name="mbs3/actuator_velocity_mbs3_joint1" class="mbs3/" joint="mbs3/mbs3_joint1" kv="0.050000000000000003"/>
    <position name="mbs3/actuator_position_mbs3_link1_joint1" class="mbs3/" joint="mbs3/mbs3_link1_joint1" kp="5"/>
    <velocity name="mbs3/actuator_velocity_mbs3_link1_joint1" class="mbs3/" joint="mbs3/mbs3_link1_joint1" kv="0.050000000000000003"/>
    <position name="mbs3/actuator_position_mbs3_link1_link1_joint1" class="mbs3/" joint="mbs3/mbs3_link1_link1_joint1" kp="5"/>
    <velocity name="mbs3/actuator_velocity_mbs3_link1_link1_joint1" class="mbs3/" joint="mbs3/mbs3_link1_link1_joint1" kv="0.050000000000000003"/>
    <position name="mbs3/actuator_position_mbs3_link1_link1_link1_joint1" class="mbs3/" joint="mbs3/mbs3_link1_link1_link1_joint1" kp="5"/>
    <velocity name="mbs3/actuator_velocity_mbs3_link1_link1_link1_joint1" class="mbs3/" joint="mbs3/mbs3_link1_link1_link1_joint1" kv="0.050000000000000003"/>
    <position name="mbs3/actuator_position_mbs3_link1_link1_link1_link1_joint1" class="mbs3/" joint="mbs3/mbs3_link1_link1_link1_link1_joint1" kp="5"/>
    <velocity name="mbs3/actuator_velocity_mbs3_link1_link1_link1_link1_joint1" class="mbs3/" joint="mbs3/mbs3_link1_link1_link1_link1_joint1" kv="0.050000000000000003"/>
    <position name="mbs3/actuator_position_mbs3_joint2" class="mbs3/" joint="mbs3/mbs3_joint2" kp="5"/>
    <velocity name="mbs3/actuator_velocity_mbs3_joint2" class="mbs3/" joint="mbs3/mbs3_joint2" kv="0.050000000000000003"/>
    <position name="mbs3/actuator_position_mbs3_link2_joint1" class="mbs3/" joint="mbs3/mbs3_link2_joint1" kp="5"/>
    <velocity name="mbs3/actuator_velocity_mbs3_link2_joint1" class="mbs3/" joint="mbs3/mbs3_link2_joint1" kv="0.050000000000000003"/>
    <position name="mbs3/actuator_position_mbs3_link2_link1_joint1" class="mbs3/" joint="mbs3/mbs3_link2_link1_joint1" kp="5"/>
    <velocity name="mbs3/actuator_velocity_mbs3_link2_link1_joint1" class="mbs3/" joint="mbs3/mbs3_link2_link1_joint1" kv="0.050000000000000003"/>
    <position name="mbs3/actuator_position_mbs3_link2_link1_link1_joint1" class="mbs3/" joint="mbs3/mbs3_link2_link1_link1_joint1" kp="5"/>
    <velocity name="mbs3/actuator_velocity_mbs3_link2_link1_link1_joint1" class="mbs3/" joint="mbs3/mbs3_link2_link1_link1_joint1" kv="0.050000000000000003"/>
    <position name="mbs3/actuator_position_mbs3_joint3" class="mbs3/" joint="mbs3/mbs3_joint3" kp="5"/>
    <velocity name="mbs3/actuator_velocity_mbs3_joint3" class="mbs3/" joint="mbs3/mbs3_joint3" kv="0.050000000000000003"/>
    <position name="mbs3/actuator_position_mbs3_link3_joint1" class="mbs3/" joint="mbs3/mbs3_link3_joint1" kp="5"/>
    <velocity name="mbs3/actuator_velocity_mbs3_link3_joint1" class="mbs3/" joint="mbs3/mbs3_link3_joint1" kv="0.050000000000000003"/>
    <position name="mbs3/actuator_position_mbs3_link3_link1_joint1" class="mbs3/" joint="mbs3/mbs3_link3_link1_joint1" kp="5"/>
    <velocity name="mbs3/actuator_velocity_mbs3_link3_link1_joint1" class="mbs3/" joint="mbs3/mbs3_link3_link1_joint1" kv="0.050000000000000003"/>
    <position name="mbs3/actuator_position_mbs3_link3_link1_link1_joint1" class="mbs3/" joint="mbs3/mbs3_link3_link1_link1_joint1" kp="5"/>
    <velocity name="mbs3/actuator_velocity_mbs3_link3_link1_link1_joint1" class="mbs3/" joint="mbs3/mbs3_link3_link1_link1_joint1" kv="0.050000000000000003"/>
    <position name="mbs3/actuator_position_mbs3_link3_link1_link1_link1_joint1" class="mbs3/" joint="mbs3/mbs3_link3_link1_link1_link1_joint1" kp="5"/>
    <velocity name="mbs3/actuator_velocity_mbs3_link3_link1_link1_link1_joint1" class="mbs3/" joint="mbs3/mbs3_link3_link1_link1_link1_joint1" kv="0.050000000000000003"/>
    <position name="mbs4/actuator_position_mbs4_joint0" class="mbs4/" joint="mbs4/mbs4_joint0" kp="5"/>
    <velocity name="mbs4/actuator_velocity_mbs4_joint0" class="mbs4/" joint="mbs4/mbs4_joint0" kv="0.050000000000000003"/>
    <position name="mbs4/actuator_position_mbs4_link0_joint1" class="mbs4/" joint="mbs4/mbs4_link0_joint1" kp="5"/>
    <velocity name="mbs4/actuator_velocity_mbs4_link0_joint1" class="mbs4/" joint="mbs4/mbs4_link0_joint1" kv="0.050000000000000003"/>
    <position name="mbs4/actuator_position_mbs4_link0_link1_joint1" class="mbs4/" joint="mbs4/mbs4_link0_link1_joint1" kp="5"/>
    <velocity name="mbs4/actuator_velocity_mbs4_link0_link1_joint1" class="mbs4/" joint="mbs4/mbs4_link0_link1_joint1" kv="0.050000000000000003"/>
    <position name="mbs4/actuator_position_mbs4_link0_link1_link1_joint1" class="mbs4/" joint="mbs4/mbs4_link0_link1_link1_joint1" kp="5"/>
    <velocity name="mbs4/actuator_velocity_mbs4_link0_link1_link1_joint1" class="mbs4/" joint="mbs4/mbs4_link0_link1_link1_joint1" kv="0.050000000000000003"/>
    <position name="mbs4/actuator_position_mbs4_link0_link1_link1_link1_joint1" class="mbs4/" joint="mbs4/mbs4_link0_link1_link1_link1_joint1" kp="5"/>
    <velocity name="mbs4/actuator_velocity_mbs4_link0_link1_link1_link1_joint1" class="mbs4/" joint="mbs4/mbs4_link0_link1_link1_link1_joint1" kv="0.050000000000000003"/>
    <position name="mbs4/actuator_position_mbs4_joint1" class="mbs4/" joint="mbs4/mbs4_joint1" kp="5"/>
    <velocity name="mbs4/actuator_velocity_mbs4_joint1" class="mbs4/" joint="mbs4/mbs4_joint1" kv="0.050000000000000003"/>
    <position name="mbs4/actuator_position_mbs4_link1_joint1" class="mbs4/" joint="mbs4/mbs4_link1_joint1" kp="5"/>
    <velocity name="mbs4/actuator_velocity_mbs4_link1_joint1" class="mbs4/" joint="mbs4/mbs4_link1_joint1" kv="0.050000000000000003"/>
    <position name="mbs4/actuator_position_mbs4_link1_link1_joint1" class="mbs4/" joint="mbs4/mbs4_link1_link1_joint1" kp="5"/>
    <velocity name="mbs4/actuator_velocity_mbs4_link1_link1_joint1" class="mbs4/" joint="mbs4/mbs4_link1_link1_joint1" kv="0.050000000000000003"/>
    <position name="mbs4/actuator_position_mbs4_link1_link1_link1_joint1" class="mbs4/" joint="mbs4/mbs4_link1_link1_link1_joint1" kp="5"/>
    <velocity name="mbs4/actuator_velocity_mbs4_link1_link1_link1_joint1" class="mbs4/" joint="mbs4/mbs4_link1_link1_link1_joint1" kv="0.050000000000000003"/>
    <position name="mbs4/actuator_position_mbs4_link1_link1_link1_link1_joint1" class="mbs4/" joint="mbs4/mbs4_link1_link1_link1_link1_joint1" kp="5"/>
    <velocity name="mbs4/actuator_velocity_mbs4_link1_link1_link1_link1_joint1" class="mbs4/" joint="mbs4/mbs4_link1_link1_link1_link1_joint1" kv="0.050000000000000003"/>
    <position name="mbs4/actuator_position_mbs4_joint2" class="mbs4/" joint="mbs4/mbs4_joint2" kp="5"/>
    <velocity name="mbs4/actuator_velocity_mbs4_joint2" class="mbs4/" joint="mbs4/mbs4_joint2" kv="0.050000000000000003"/>
    <position name="mbs4/actuator_position_mbs4_link2_joint1" class="mbs4/" joint="mbs4/mbs4_link2_joint1" kp="5"/>
    <velocity name="mbs4/actuator_velocity_mbs4_link2_joint1" class="mbs4/" joint="mbs4/mbs4_link2_joint1" kv="0.050000000000000003"/>
    <position name="mbs4/actuator_position_mbs4_link2_link1_joint1" class="mbs4/" joint="mbs4/mbs4_link2_link1_joint1" kp="5"/>
    <velocity name="mbs4/actuator_velocity_mbs4_link2_link1_joint1" class="mbs4/" joint="mbs4/mbs4_link2_link1_joint1" kv="0.050000000000000003"/>
    <position name="mbs4/actuator_position_mbs4_link2_link1_link1_joint1" class="mbs4/" joint="mbs4/mbs4_link2_link1_link1_joint1" kp="5"/>
    <velocity name="mbs4/actuator_velocity_mbs4_link2_link1_link1_joint1" class="mbs4/" joint="mbs4/mbs4_link2_link1_link1_joint1" kv="0.050000000000000003"/>
    <position name="mbs4/actuator_position_mbs4_joint3" class="mbs4/" joint="mbs4/mbs4_joint3" kp="5"/>
    <velocity name="mbs4/actuator_velocity_mbs4_joint3" class="mbs4/" joint="mbs4/mbs4_joint3" kv="0.050000000000000003"/>
    <position name="mbs4/actuator_position_mbs4_link3_joint1" class="mbs4/" joint="mbs4/mbs4_link3_joint1" kp="5"/>
    <velocity name="mbs4/actuator_velocity_mbs4_link3_joint1" class="mbs4/" joint="mbs4/mbs4_link3_joint1" kv="0.050000000000000003"/>
    <position name="mbs4/actuator_position_mbs4_link3_link1_joint1" class="mbs4/" joint="mbs4/mbs4_link3_link1_joint1" kp="5"/>
    <velocity name="mbs4/actuator_velocity_mbs4_link3_link1_joint1" class="mbs4/" joint="mbs4/mbs4_link3_link1_joint1" kv="0.050000000000000003"/>
    <position name="mbs4/actuator_position_mbs4_link3_link1_link1_joint1" class="mbs4/" joint="mbs4/mbs4_link3_link1_link1_joint1" kp="5"/>
    <velocity name="mbs4/actuator_velocity_mbs4_link3_link1_link1_joint1" class="mbs4/" joint="mbs4/mbs4_link3_link1_link1_joint1" kv="0.050000000000000003"/>
    <position name="mbs4/actuator_position_mbs4_link3_link1_link1_link1_joint1" class="mbs4/" joint="mbs4/mbs4_link3_link1_link1_link1_joint1" kp="5"/>
    <velocity name="mbs4/actuator_velocity_mbs4_link3_link1_link1_link1_joint1" class="mbs4/" joint="mbs4/mbs4_link3_link1_link1_link1_joint1" kv="0.050000000000000003"/>
  </actuator>
</mujoco>
